Module message: Setting OPENBLAS_NUM_THREADS to 1. Done. 
Traceback (most recent call last):
  File "/hpcfs/users/a1670295/Sampling/Python/phoenix_hSBM.py", line 4, in <module>
/apps/skl/software/R/4.0.3/lib64/R/bin/BATCH: line 60: 99098 Killed                  ${R_HOME}/bin/R -f ${in} ${opts} ${R_BATCH_OPTIONS} > ${out} 2>&1
./my_program.sh: line 16: /hpcfs/users/a1670295/myconda/envs/gt/bin/python3.9: Argument list too long
./my_program.sh: line 16: /hpcfs/users/a1670295/myconda/envs/gt/bin/python3.9: Argument list too long
./my_program.sh: line 16: /hpcfs/users/a1670295/myconda/envs/gt/bin/python3.9: Argument list too long
./my_program.sh: line 16: /hpcfs/users/a1670295/myconda/envs/gt/bin/python3.9: Argument list too long
./my_program.sh: line 16: /hpcfs/users/a1670295/myconda/envs/gt/bin/python3.9: Argument list too long
./my_program.sh: line 16: /hpcfs/users/a1670295/myconda/envs/gt/bin/python3.9: Argument list too long
./my_program.sh: line 16: /hpcfs/users/a1670295/myconda/envs/gt/bin/python3.9: Argument list too long
./my_program.sh: line 16: /hpcfs/users/a1670295/myconda/envs/gt/bin/python3.9: Argument list too long
./my_program.sh: line 16: /hpcfs/users/a1670295/myconda/envs/gt/bin/python3.9: Argument list too long
./my_program.sh: line 16: /hpcfs/users/a1670295/myconda/envs/gt/bin/python3.9: Argument list too long
./my_program.sh: line 16: /hpcfs/users/a1670295/myconda/envs/gt/bin/python3.9: Argument list too long

** (process:98617): WARNING **: 23:22:06.108: Failed to load shared library 'libpango-1.0.so.0' referenced by the typelib: /hpcfs/users/a1670295/myconda/envs/gt/lib/python3.9/site-packages/gi/../../.././././libfribidi.so.0: cannot read file data: Cannot allocate memory
Traceback (most recent call last):
  File "/hpcfs/users/a1670295/Sampling/Python/phoenix_hSBM.py", line 4, in <module>
Python path configuration:
  PYTHONHOME = (not set)
  PYTHONPATH = '/apps/skl/software/GDAL/2.2.3/lib/python3.6/site-packages:/apps/skl/software/GEOS/3.6.2/lib/python3.6/site-packages'
  program name = 'python3.9'
  isolated = 0
  environment = 1
  user site = 1
  import site = 1
  sys._base_executable = '/hpcfs/users/a1670295/myconda/envs/gt/bin/python3.9'
  sys.base_prefix = '/hpcfs/users/a1670295/myconda/envs/gt'
  sys.base_exec_prefix = '/hpcfs/users/a1670295/myconda/envs/gt'
  sys.platlibdir = 'lib'
  sys.executable = '/hpcfs/users/a1670295/myconda/envs/gt/bin/python3.9'
  sys.prefix = '/hpcfs/users/a1670295/myconda/envs/gt'
  sys.exec_prefix = '/hpcfs/users/a1670295/myconda/envs/gt'
  sys.path = [
    '/apps/skl/software/GDAL/2.2.3/lib/python3.6/site-packages',
    '/apps/skl/software/GEOS/3.6.2/lib/python3.6/site-packages',
    '/hpcfs/users/a1670295/myconda/envs/gt/lib/python39.zip',
    '/hpcfs/users/a1670295/myconda/envs/gt/lib/python3.9',
    '/hpcfs/users/a1670295/myconda/envs/gt/lib/python3.9/lib-dynload',
  ]
Fatal Python error: init_fs_encoding: failed to get the Python codec of the filesystem encoding
Python runtime state: core initialized
    from sbmtm import sbmtm
Python path configuration:
  PYTHONHOME = (not set)
  PYTHONPATH = '/apps/skl/software/GDAL/2.2.3/lib/python3.6/site-packages:/apps/skl/software/GEOS/3.6.2/lib/python3.6/site-packages'
  program name = 'python3.9'
  isolated = 0
  environment = 1
  user site = 1
  import site = 1
  sys._base_executable =   File "/hpcfs/users/a1670295/Sampling/Python/sbmtm.py", line 8, in <module>
Traceback (most recent call last):
  File "/hpcfs/users/a1670295/myconda/envs/gt/lib/python3.9/encodings/__init__.py", line 33, in <module>
  File "<frozen importlib._bootstrap>", line 1007, in _find_and_load
  File "<frozen importlib._bootstrap>", line 982, in _find_and_load_unlocked
  File "<frozen importlib._bootstrap>", line 925, in _find_spec
  File "<frozen importlib._bootstrap_external>", line 1349, in find_spec
    import graph_tool.all as gt
  File "/hpcfs/users/a1670295/myconda/envs/gt/lib/python3.9/site-packages/graph_tool/all.py", line 34, in <module>
  File "<frozen importlib._bootstrap_external>", line 1321, in _get_spec
  File "<frozen importlib._bootstrap_external>", line 1450, in find_spec
  File "<frozen importlib._bootstrap_external>", line 1490, in _fill_cache
OSError: [Errno 12] Cannot allocate memory: '/hpcfs/users/a1670295/myconda/envs/gt/lib/python3.9/encodings'
    from graph_tool.draw import *
  File "/hpcfs/users/a1670295/myconda/envs/gt/lib/python3.9/site-packages/graph_tool/draw/__init__.py", line 876, in <module>
'/hpcfs/users/a1670295/myconda/envs/gt/bin/python3.9'
  sys.base_prefix = '/hpcfs/users/a1670295/myconda/envs/gt'
  sys.base_exec_prefix = '/hpcfs/users/a1670295/myconda/envs/gt'
  sys.platlibdir = 'lib'
  sys.executable = '/hpcfs/users/a1670295/myconda/envs/gt/bin/python3.9'
  sys.prefix = '/hpcfs/users/a1670295/myconda/envs/gt'
  sys.exec_prefix = '/hpcfs/users/a1670295/myconda/envs/gt'
  sys.path = [
    '/apps/skl/software/GDAL/2.2.3/lib/python3.6/site-packages',
    '/apps/skl/software/GEOS/3.6.2/lib/python3.6/site-packages',
    '/hpcfs/users/a1670295/myconda/envs/gt/lib/python39.zip',
    '/hpcfs/users/a1670295/myconda/envs/gt/lib/python3.9',
    '/hpcfs/users/a1670295/myconda/envs/gt/lib/python3.9/lib-dynload',
  ]
Fatal Python error: init_fs_encoding: failed to get the Python codec of the filesystem encoding
Python runtime state: core initialized
Traceback (most recent call last):
  File "<frozen importlib._bootstrap>", line 1007, in _find_and_load
    from . cairo_draw import graph_draw, cairo_draw, \
  File "/hpcfs/users/a1670295/myconda/envs/gt/lib/python3.9/site-packages/graph_tool/draw/cairo_draw.py", line 1496, in <module>
    from gi.repository import Gtk, Gdk, GdkPixbuf
  File "<frozen importlib._bootstrap>", line 1007, in _find_and_load
  File "<frozen importlib._bootstrap>", line 982, in _find_and_load_unlocked
  File "<frozen importlib._bootstrap>", line 925, in _find_spec
  File "<frozen importlib._bootstrap_external>", line 1349, in find_spec
  File "<frozen importlib._bootstrap_external>", line 1321, in _get_spec
  File "<frozen importlib._bootstrap_external>", line 1450, in find_spec
  File "<frozen importlib._bootstrap_external>", line 1490, in _fill_cache
OSError: [Errno 12] Cannot allocate memory: '/hpcfs/users/a1670295/myconda/envs/gt/lib/python3.9'
Error processing line 1 of /hpcfs/users/a1670295/myconda/envs/gt/lib/python3.9/site-packages/matplotlib-3.3.4-py3.9-nspkg.pth:

./my_program.sh: line 16: /hpcfs/users/a1670295/myconda/envs/gt/bin/python3.9: Argument list too long
./my_program.sh: line 16: /hpcfs/users/a1670295/myconda/envs/gt/bin/python3.9: Argument list too long
./my_program.sh: line 16: /hpcfs/users/a1670295/myconda/envs/gt/bin/python3.9: Argument list too long
./my_program.sh: line 16: /hpcfs/users/a1670295/myconda/envs/gt/bin/python3.9: Argument list too long
./my_program.sh: line 18: 98475 Killed                  python3.9 Python/phoenix_hSBM.py $i
./my_program.sh: line 18: 98523 Killed                  python3.9 Python/phoenix_hSBM.py $i
./my_program.sh: line 18: 98539 Killed                  python3.9 Python/phoenix_hSBM.py $i
./my_program.sh: line 18: 98653 Killed                  python3.9 Python/phoenix_hSBM.py $i
./my_program.sh: line 18: 98654 Killed                  python3.9 Python/phoenix_hSBM.py $i
./my_program.sh: line 18: 98669 Killed                  python3.9 Python/phoenix_hSBM.py $i
./my_program.sh: line 18: 98703 Killed                  python3.9 Python/phoenix_hSBM.py $i
./my_program.sh: line 18: 99583 Segmentation fault      python3.9 Python/phoenix_tree_dist.py $i
./my_program.sh: line 18: 99594 Segmentation fault      python3.9 Python/phoenix_tree_dist.py $i
./my_program.sh: line 18: 99634 Segmentation fault      python3.9 Python/phoenix_tree_dist.py $i
./my_program.sh: line 18: 99653 Segmentation fault      python3.9 Python/phoenix_tree_dist.py $i
./my_program.sh: line 18: 99667 Segmentation fault      python3.9 Python/phoenix_tree_dist.py $i
./my_program.sh: line 18: 99737 Segmentation fault      python3.9 Python/phoenix_tree_dist.py $i
./my_program.sh: line 18: 99742 Segmentation fault      python3.9 Python/phoenix_tree_dist.py $i
./my_program.sh: line 18: 99748 Segmentation fault      python3.9 Python/phoenix_tree_dist.py $i
./my_program.sh: line 18: 99750 Segmentation fault      python3.9 Python/phoenix_tree_dist.py $i
  File "<frozen importlib._bootstrap>", line 986, in _find_and_load_unlocked
  File "<frozen importlib._bootstrap>", line 664, in _load_unlocked
  File "<frozen importlib._bootstrap>", line 627, in _load_backward_compatible
  File "/hpcfs/users/a1670295/myconda/envs/gt/lib/python3.9/site-packages/gi/importer.py", line 144, in load_module
    importlib.import_module('gi.repository.' + dep.split("-")[0])
  File "/hpcfs/users/a1670295/myconda/envs/gt/lib/python3.9/importlib/__init__.py", line 127, in import_module
    return _bootstrap._gcd_import(name[level:], package, level)
  File "<frozen importlib._bootstrap>", line 1030, in _gcd_import
  File "<frozen importlib._bootstrap>", line 1007, in _find_and_load
  File "<frozen importlib._bootstrap>", line 986, in _find_and_load_unlocked
  File "<frozen importlib._bootstrap>", line 664, in _load_unlocked
  File "<frozen importlib._bootstrap>", line 627, in _load_backward_compatible
  File "/hpcfs/users/a1670295/myconda/envs/gt/lib/python3.9/site-packages/gi/importer.py", line 144, in load_module
    importlib.import_module('gi.repository.' + dep.split("-")[0])
  File "/hpcfs/users/a1670295/myconda/envs/gt/lib/python3.9/importlib/__init__.py", line 127, in import_module
    return _bootstrap._gcd_import(name[level:], package, level)
  File "<frozen importlib._bootstrap>", line 1030, in _gcd_import
  File "<frozen importlib._bootstrap>", line 1007, in _find_and_load
  File "<frozen importlib._bootstrap>", line 986, in _find_and_load_unlocked
  File "<frozen importlib._bootstrap>", line 664, in _load_unlocked
  File "<frozen importlib._bootstrap>", line 627, in _load_backward_compatible
  File "/hpcfs/users/a1670295/myconda/envs/gt/lib/python3.9/site-packages/gi/importer.py", line 145, in load_module
    dynamic_module = load_overrides(introspection_module)
  File "/hpcfs/users/a1670295/myconda/envs/gt/lib/python3.9/site-packages/gi/overrides/__init__.py", line 118, in load_overrides
    override_mod = importlib.import_module(override_package_name)
  File "/hpcfs/users/a1670295/myconda/envs/gt/lib/python3.9/importlib/__init__.py", line 127, in import_module
    return _bootstrap._gcd_import(name[level:], package, level)
  File "/hpcfs/users/a1670295/myconda/envs/gt/lib/python3.9/site-packages/gi/overrides/Pango.py", line 41, in <module>
    FontDescription = override(FontDescription)
  File "/hpcfs/users/a1670295/myconda/envs/gt/lib/python3.9/site-packages/gi/overrides/__init__.py", line 195, in override
    assert g_type != TYPE_NONE
AssertionError
    from sbmtm import sbmtm
  File "/hpcfs/users/a1670295/Sampling/Python/sbmtm.py", line 8, in <module>
/apps/skl/software/R/4.0.3/lib64/R/bin/BATCH: line 60: 299521 Killed                  ${R_HOME}/bin/R -f ${in} ${opts} ${R_BATCH_OPTIONS} > ${out} 2>&1
    import graph_tool.all as gt
  File "/hpcfs/users/a1670295/myconda/envs/gt/lib/python3.9/site-packages/graph_tool/all.py", line 34, in <module>
    from graph_tool.draw import *
  File "/hpcfs/users/a1670295/myconda/envs/gt/lib/python3.9/site-packages/graph_tool/draw/__init__.py", line 876, in <module>
    from . cairo_draw import graph_draw, cairo_draw, \
  File "/hpcfs/users/a1670295/myconda/envs/gt/lib/python3.9/site-packages/graph_tool/draw/cairo_draw.py", line 64, in <module>
Traceback (most recent call last):
  File "/hpcfs/users/a1670295/Sampling/Python/phoenix_hSBM.py", line 4, in <module>
    import IPython.display
  File "/hpcfs/users/a1670295/myconda/envs/gt/lib/python3.9/site-packages/IPython/__init__.py", line 56, in <module>
    from sbmtm import sbmtm
  File "/hpcfs/users/a1670295/Sampling/Python/sbmtm.py", line 8, in <module>
    import graph_tool.all as gt
  File "/hpcfs/users/a1670295/myconda/envs/gt/lib/python3.9/site-packages/graph_tool/all.py", line 34, in <module>
    from graph_tool.draw import *
  File "/hpcfs/users/a1670295/myconda/envs/gt/lib/python3.9/site-packages/graph_tool/draw/__init__.py", line 876, in <module>
    from .terminal.embed import embed
  File "/hpcfs/users/a1670295/myconda/envs/gt/lib/python3.9/site-packages/IPython/terminal/embed.py", line 16, in <module>
    from IPython.terminal.interactiveshell import TerminalInteractiveShell
  File "/hpcfs/users/a1670295/myconda/envs/gt/lib/python3.9/site-packages/IPython/terminal/interactiveshell.py", line 35, in <module>
    from .debugger import TerminalPdb, Pdb
  File "/hpcfs/users/a1670295/myconda/envs/gt/lib/python3.9/site-packages/IPython/terminal/debugger.py", line 8, in <module>
    from IPython.core.completer import IPCompleter
  File "/hpcfs/users/a1670295/myconda/envs/gt/lib/python3.9/site-packages/IPython/core/completer.py", line 146, in <module>
    import jedi
  File "/hpcfs/users/a1670295/myconda/envs/gt/lib/python3.9/site-packages/jedi/__init__.py", line 32, in <module>
    from jedi.api import Script, Interpreter, set_debug_function, preload_module
  File "/hpcfs/users/a1670295/myconda/envs/gt/lib/python3.9/site-packages/jedi/api/__init__.py", line 22, in <module>
    from jedi.api import classes
  File "/hpcfs/users/a1670295/myconda/envs/gt/lib/python3.9/site-packages/jedi/api/classes.py", line 24, in <module>
    from jedi.inference.utils import unite
  File "/hpcfs/users/a1670295/myconda/envs/gt/lib/python3.9/site-packages/jedi/inference/__init__.py", line 70, in <module>
    from jedi.inference import imports
  File "/hpcfs/users/a1670295/myconda/envs/gt/lib/python3.9/site-packages/jedi/inference/imports.py", line 23, in <module>
  Traceback (most recent call last):
    File "/hpcfs/users/a1670295/myconda/envs/gt/lib/python3.9/site.py", line 169, in addpackage
      exec(line)
    File "<string>", line 1, in <module>
    File "<frozen importlib._bootstrap>", line 1007, in _find_and_load
    File "<frozen importlib._bootstrap>", line 986, in _find_and_load_unlocked
    File "<frozen importlib._bootstrap>", line 680, in _load_unlocked
    File "<frozen importlib._bootstrap_external>", line 786, in exec_module
    File "<frozen importlib._bootstrap_external>", line 922, in get_code
    File "<frozen importlib._bootstrap_external>", line 980, in get_data
  OSError: [Errno 12] Cannot allocate memory

Remainder of file ignored
Fatal Python error: init_import_site: Failed to import the site module
Python runtime state: initialized
Traceback (most recent call last):
  File "/hpcfs/users/a1670295/myconda/envs/gt/lib/python3.9/site.py", line 589, in <module>
    main()
  File "/hpcfs/users/a1670295/myconda/envs/gt/lib/python3.9/site.py", line 576, in main
    known_paths = addsitepackages(known_paths)
  File "/hpcfs/users/a1670295/myconda/envs/gt/lib/python3.9/site.py", line 359, in addsitepackages
    addsitedir(sitedir, known_paths)
  File "/hpcfs/users/a1670295/myconda/envs/gt/lib/python3.9/site.py", line 208, in addsitedir
    addpackage(sitedir, name, known_paths)
  File "/hpcfs/users/a1670295/myconda/envs/gt/lib/python3.9/site.py", line 164, in addpackage
    for n, line in enumerate(f):
OSError: [Errno 12] Cannot allocate memory
Traceback (most recent call last):
  File "/hpcfs/users/a1670295/myconda/envs/gt/lib/python3.9/site-packages/numpy/compat/py3k.py", line 28, in <module>
Traceback (most recent call last):
  File "/hpcfs/users/a1670295/Sampling/Python/phoenix_hSBM.py", line 4, in <module>
    from sbmtm import sbmtm
  File "/hpcfs/users/a1670295/Sampling/Python/sbmtm.py", line 8, in <module>
    import graph_tool.all as gt
  File "/hpcfs/users/a1670295/myconda/envs/gt/lib/python3.9/site-packages/graph_tool/all.py", line 34, in <module>
    from graph_tool.draw import *
  File "/hpcfs/users/a1670295/myconda/envs/gt/lib/python3.9/site-packages/graph_tool/draw/__init__.py", line 876, in <module>
    import pickle5 as pickle
ModuleNotFoundError: No module named 'pickle5'

During handling of the above exception, another exception occurred:

Traceback (most recent call last):
  File "/hpcfs/users/a1670295/Sampling/Python/phoenix_tree_dist.py", line 1, in <module>
    import pandas as pd
  File "/hpcfs/users/a1670295/myconda/envs/gt/lib/python3.9/site-packages/pandas/__init__.py", line 11, in <module>
    from . cairo_draw import graph_draw, cairo_draw, \
  File "/hpcfs/users/a1670295/myconda/envs/gt/lib/python3.9/site-packages/graph_tool/draw/cairo_draw.py", line 64, in <module>
    __import__(dependency)
  File "/hpcfs/users/a1670295/myconda/envs/gt/lib/python3.9/site-packages/numpy/__init__.py", line 145, in <module>
    import IPython.display
  File "/hpcfs/users/a1670295/myconda/envs/gt/lib/python3.9/site-packages/IPython/__init__.py", line 56, in <module>
    from .terminal.embed import embed
  File "/hpcfs/users/a1670295/myconda/envs/gt/lib/python3.9/site-packages/IPython/terminal/embed.py", line 16, in <module>
    from . import core
  File "/hpcfs/users/a1670295/myconda/envs/gt/lib/python3.9/site-packages/numpy/core/__init__.py", line 22, in <module>
    from IPython.terminal.interactiveshell import TerminalInteractiveShell
  File "/hpcfs/users/a1670295/myconda/envs/gt/lib/python3.9/site-packages/IPython/terminal/interactiveshell.py", line 19, in <module>
    from . import multiarray
  File "/hpcfs/users/a1670295/myconda/envs/gt/lib/python3.9/site-packages/numpy/core/multiarray.py", line 12, in <module>
    from prompt_toolkit.enums import DEFAULT_BUFFER, EditingMode
  File "/hpcfs/users/a1670295/myconda/envs/gt/lib/python3.9/site-packages/prompt_toolkit/__init__.py", line 16, in <module>
Traceback (most recent call last):
  File "/hpcfs/users/a1670295/Sampling/Python/phoenix_hSBM.py", line 4, in <module>
Traceback (most recent call last):
  File "/hpcfs/users/a1670295/Sampling/Python/phoenix_hSBM.py", line 4, in <module>
    from . import overrides
  File "/hpcfs/users/a1670295/myconda/envs/gt/lib/python3.9/site-packages/numpy/core/overrides.py", line 9, in <module>
    from sbmtm import sbmtm
  File "/hpcfs/users/a1670295/Sampling/Python/sbmtm.py", line 8, in <module>
    import graph_tool.all as gt
  File "/hpcfs/users/a1670295/myconda/envs/gt/lib/python3.9/site-packages/graph_tool/all.py", line 34, in <module>
    from numpy.compat._inspect import getargspec
  File "/hpcfs/users/a1670295/myconda/envs/gt/lib/python3.9/site-packages/numpy/compat/__init__.py", line 12, in <module>
    from .application import Application
  File "/hpcfs/users/a1670295/myconda/envs/gt/lib/python3.9/site-packages/prompt_toolkit/application/__init__.py", line 1, in <module>
    from sbmtm import sbmtm
  File "/hpcfs/users/a1670295/Sampling/Python/sbmtm.py", line 8, in <module>
    from graph_tool.draw import *
  File "/hpcfs/users/a1670295/myconda/envs/gt/lib/python3.9/site-packages/graph_tool/draw/__init__.py", line 876, in <module>
    import graph_tool.all as gt
  File "/hpcfs/users/a1670295/myconda/envs/gt/lib/python3.9/site-packages/graph_tool/all.py", line 34, in <module>
    from . cairo_draw import graph_draw, cairo_draw, \
  File "/hpcfs/users/a1670295/myconda/envs/gt/lib/python3.9/site-packages/graph_tool/draw/cairo_draw.py", line 64, in <module>
    from graph_tool.draw import *
  File "/hpcfs/users/a1670295/myconda/envs/gt/lib/python3.9/site-packages/graph_tool/draw/__init__.py", line 876, in <module>
    import IPython.display
  File "/hpcfs/users/a1670295/myconda/envs/gt/lib/python3.9/site-packages/IPython/__init__.py", line 56, in <module>
    from .terminal.embed import embed
  File "/hpcfs/users/a1670295/myconda/envs/gt/lib/python3.9/site-packages/IPython/terminal/embed.py", line 16, in <module>
    from IPython.terminal.interactiveshell import TerminalInteractiveShell
  File "/hpcfs/users/a1670295/myconda/envs/gt/lib/python3.9/site-packages/IPython/terminal/interactiveshell.py", line 35, in <module>
    from . import py3k
  File "/hpcfs/users/a1670295/myconda/envs/gt/lib/python3.9/site-packages/numpy/compat/py3k.py", line 30, in <module>
    from .application import Application
  File "/hpcfs/users/a1670295/myconda/envs/gt/lib/python3.9/site-packages/prompt_toolkit/application/application.py", line 42, in <module>
    import pickle
  File "<frozen importlib._bootstrap>", line 1007, in _find_and_load
  File "<frozen importlib._bootstrap>", line 986, in _find_and_load_unlocked
  File "<frozen importlib._bootstrap>", line 680, in _load_unlocked
  File "<frozen importlib._bootstrap_external>", line 786, in exec_module
    from . cairo_draw import graph_draw, cairo_draw, \
  File "/hpcfs/users/a1670295/myconda/envs/gt/lib/python3.9/site-packages/graph_tool/draw/cairo_draw.py", line 64, in <module>
  File "<frozen importlib._bootstrap_external>", line 922, in get_code
  File "<frozen importlib._bootstrap_external>", line 980, in get_data
OSError: [Errno 12] Cannot allocate memory
    import IPython.display
  File "/hpcfs/users/a1670295/myconda/envs/gt/lib/python3.9/site-packages/IPython/__init__.py", line 56, in <module>
    from .debugger import TerminalPdb, Pdb
  File "/hpcfs/users/a1670295/myconda/envs/gt/lib/python3.9/site-packages/IPython/terminal/debugger.py", line 8, in <module>
    from .terminal.embed import embed
  File "/hpcfs/users/a1670295/myconda/envs/gt/lib/python3.9/site-packages/IPython/terminal/embed.py", line 16, in <module>
    from prompt_toolkit.buffer import Buffer
  File "/hpcfs/users/a1670295/myconda/envs/gt/lib/python3.9/site-packages/prompt_toolkit/buffer.py", line 33, in <module>
    from IPython.core.completer import IPCompleter
  File "/hpcfs/users/a1670295/myconda/envs/gt/lib/python3.9/site-packages/IPython/core/completer.py", line 146, in <module>
    from .auto_suggest import AutoSuggest, Suggestion
  File "/hpcfs/users/a1670295/myconda/envs/gt/lib/python3.9/site-packages/prompt_toolkit/auto_suggest.py", line 19, in <module>
Fatal Python error: init_import_site: Failed to import the site module
Python runtime state: initialized
Traceback (most recent call last):
  File "/hpcfs/users/a1670295/myconda/envs/gt/lib/python3.9/site.py", line 589, in <module>
    import jedi
  File "/hpcfs/users/a1670295/myconda/envs/gt/lib/python3.9/site-packages/jedi/__init__.py", line 32, in <module>
    from .document import Document
  File "/hpcfs/users/a1670295/myconda/envs/gt/lib/python3.9/site-packages/prompt_toolkit/document.py", line 10, in <module>
    main()
  File "/hpcfs/users/a1670295/myconda/envs/gt/lib/python3.9/site.py", line 576, in main
    from IPython.terminal.interactiveshell import TerminalInteractiveShell
  File "/hpcfs/users/a1670295/myconda/envs/gt/lib/python3.9/site-packages/IPython/terminal/interactiveshell.py", line 35, in <module>
Python path configuration:
  PYTHONHOME = (not set)
  PYTHONPATH = '/apps/skl/software/GDAL/2.2.3/lib/python3.6/site-packages:/apps/skl/software/GEOS/3.6.2/lib/python3.6/site-packages'
  program name = 'python3.9'
  isolated = 0
  environment = 1
  user site = 1
  import site = 1
  sys._base_executable = '/hpcfs/users/a1670295/myconda/envs/gt/bin/python3.9'
  sys.base_prefix = '/hpcfs/users/a1670295/myconda/envs/gt'
  sys.base_exec_prefix = '/hpcfs/users/a1670295/myconda/envs/gt'
  sys.platlibdir = 'lib'
  sys.executable = '/hpcfs/users/a1670295/myconda/envs/gt/bin/python3.9'
  sys.prefix = '/hpcfs/users/a1670295/myconda/envs/gt'
  sys.exec_prefix = '/hpcfs/users/a1670295/myconda/envs/gt'
  sys.path = [
    '/apps/skl/software/GDAL/2.2.3/lib/python3.6/site-packages',
    '/apps/skl/software/GEOS/3.6.2/lib/python3.6/site-packages',
    '/hpcfs/users/a1670295/myconda/envs/gt/lib/python39.zip',
    '/hpcfs/users/a1670295/myconda/envs/gt/lib/python3.9',
    '/hpcfs/users/a1670295/myconda/envs/gt/lib/python3.9/lib-dynload',
  ]
Python path configuration:
  PYTHONHOME = (not set)
  PYTHONPATH = '/apps/skl/software/GDAL/2.2.3/lib/python3.6/site-packages:/apps/skl/software/GEOS/3.6.2/lib/python3.6/site-packages'
  program name = 'python3.9'
  isolated = 0
  environment = 1
  user site = 1
  import site = 1
  sys._base_executable = '/hpcfs/users/a1670295/myconda/envs/gt/bin/python3.9'
  sys.base_prefix = '/hpcfs/users/a1670295/myconda/envs/gt'
  sys.base_exec_prefix = '/hpcfs/users/a1670295/myconda/envs/gt'
  sys.platlibdir = 'lib'
  sys.executable = '/hpcfs/users/a1670295/myconda/envs/gt/bin/python3.9'
  sys.prefix = '/hpcfs/users/a1670295/myconda/envs/gt'
  sys.exec_prefix = '/hpcfs/users/a1670295/myconda/envs/gt'
  sys.path = [
    '/apps/skl/software/GDAL/2.2.3/lib/python3.6/site-packages',
    '/apps/skl/software/GEOS/3.6.2/lib/python3.6/site-packages',
    '/hpcfs/users/a1670295/myconda/envs/gt/lib/python39.zip',
    '/hpcfs/users/a1670295/myconda/envs/gt/lib/python3.9',
    '/hpcfs/users/a1670295/myconda/envs/gt/lib/python3.9/lib-dynload',
  ]
Python path configuration:
  PYTHONHOME = (not set)
  PYTHONPATH = '/apps/skl/software/GDAL/2.2.3/lib/python3.6/site-packages:/apps/skl/software/GEOS/3.6.2/lib/python3.6/site-packages'
  program name = 'python3.9'
  isolated = 0
  environment = 1
  user site = 1
  import site = 1
  sys._base_executable = '/hpcfs/users/a1670295/myconda/envs/gt/bin/python3.9'
  sys.base_prefix = '/hpcfs/users/a1670295/myconda/envs/gt'
  sys.base_exec_prefix = '/hpcfs/users/a1670295/myconda/envs/gt'
  sys.platlibdir = 'lib'
  sys.executable = '/hpcfs/users/a1670295/myconda/envs/gt/bin/python3.9'
  sys.prefix = '/hpcfs/users/a1670295/myconda/envs/gt'
  sys.exec_prefix = '/hpcfs/users/a1670295/myconda/envs/gt'
  sys.path = [
    '/apps/skl/software/GDAL/2.2.3/lib/python3.6/site-packages',
    '/apps/skl/software/GEOS/3.6.2/lib/python3.6/site-packages',
    '/hpcfs/users/a1670295/myconda/envs/gt/lib/python39.zip',
    '/hpcfs/users/a1670295/myconda/envs/gt/lib/python3.9',
    '/hpcfs/users/a1670295/myconda/envs/gt/lib/python3.9/lib-dynload',
  ]
Python path configuration:
  PYTHONHOME = (not set)
  PYTHONPATH = '/apps/skl/software/GDAL/2.2.3/lib/python3.6/site-packages:/apps/skl/software/GEOS/3.6.2/lib/python3.6/site-packages'
  program name = 'python3.9'
  isolated = 0
  environment = 1
  user site = 1
  import site = 1
  sys._base_executable = '/hpcfs/users/a1670295/myconda/envs/gt/bin/python3.9'
  sys.base_prefix = '/hpcfs/users/a1670295/myconda/envs/gt'
  sys.base_exec_prefix = '/hpcfs/users/a1670295/myconda/envs/gt'
  sys.platlibdir = 'lib'
  sys.executable = '/hpcfs/users/a1670295/myconda/envs/gt/bin/python3.9'
  sys.prefix = '/hpcfs/users/a1670295/myconda/envs/gt'
  sys.exec_prefix = '/hpcfs/users/a1670295/myconda/envs/gt'
  sys.path = [
    '/apps/skl/software/GDAL/2.2.3/lib/python3.6/site-packages',
    '/apps/skl/software/GEOS/3.6.2/lib/python3.6/site-packages',
    '/hpcfs/users/a1670295/myconda/envs/gt/lib/python39.zip',
    '/hpcfs/users/a1670295/myconda/envs/gt/lib/python3.9',
    '/hpcfs/users/a1670295/myconda/envs/gt/lib/python3.9/lib-dynload',
  ]
Python path configuration:
  PYTHONHOME = (not set)
  PYTHONPATH = '/apps/skl/software/GDAL/2.2.3/lib/python3.6/site-packages:/apps/skl/software/GEOS/3.6.2/lib/python3.6/site-packages'
  program name = 'python3.9'
  isolated = 0
  environment = 1
  user site = 1
  import site = 1
  sys._base_executable = '/hpcfs/users/a1670295/myconda/envs/gt/bin/python3.9'
  sys.base_prefix = '/hpcfs/users/a1670295/myconda/envs/gt'
  sys.base_exec_prefix = '/hpcfs/users/a1670295/myconda/envs/gt'
  sys.platlibdir = 'lib'
  sys.executable = '/hpcfs/users/a1670295/myconda/envs/gt/bin/python3.9'
  sys.prefix = '/hpcfs/users/a1670295/myconda/envs/gt'
  sys.exec_prefix = '/hpcfs/users/a1670295/myconda/envs/gt'
  sys.path = [
    '/apps/skl/software/GDAL/2.2.3/lib/python3.6/site-packages',
    '/apps/skl/software/GEOS/3.6.2/lib/python3.6/site-packages',
    '/hpcfs/users/a1670295/myconda/envs/gt/lib/python39.zip',
    '/hpcfs/users/a1670295/myconda/envs/gt/lib/python3.9',
    '/hpcfs/users/a1670295/myconda/envs/gt/lib/python3.9/lib-dynload',
  ]
Python path configuration:
  PYTHONHOME = (not set)
  PYTHONPATH = '/apps/skl/software/GDAL/2.2.3/lib/python3.6/site-packages:/apps/skl/software/GEOS/3.6.2/lib/python3.6/site-packages'
  program name = 'python3.9'
  isolated = 0
  environment = 1
  user site = 1
  import site = 1
  sys._base_executable = '/hpcfs/users/a1670295/myconda/envs/gt/bin/python3.9'
  sys.base_prefix = '/hpcfs/users/a1670295/myconda/envs/gt'
  sys.base_exec_prefix = '/hpcfs/users/a1670295/myconda/envs/gt'
  sys.platlibdir = 'lib'
  sys.executable = '/hpcfs/users/a1670295/myconda/envs/gt/bin/python3.9'
  sys.prefix = '/hpcfs/users/a1670295/myconda/envs/gt'
  sys.exec_prefix = '/hpcfs/users/a1670295/myconda/envs/gt'
  sys.path = [
    '/apps/skl/software/GDAL/2.2.3/lib/python3.6/site-packages',
    '/apps/skl/software/GEOS/3.6.2/lib/python3.6/site-packages',
    '/hpcfs/users/a1670295/myconda/envs/gt/lib/python39.zip',
    '/hpcfs/users/a1670295/myconda/envs/gt/lib/python3.9',
    '/hpcfs/users/a1670295/myconda/envs/gt/lib/python3.9/lib-dynload',
  ]
Fatal Python error: init_fs_encoding: failed to get the Python codec of the filesystem encoding
Python runtime state: core initialized
Traceback (most recent call last):
  File "<frozen importlib._bootstrap>", line 1007, in _find_and_load
Fatal Python error: init_fs_encoding: failed to get the Python codec of the filesystem encoding
Python runtime state: core initialized
Fatal Python error: init_fs_encoding: failed to get the Python codec of the filesystem encoding
Python runtime state: core initialized
Fatal Python error: init_fs_encoding: failed to get the Python codec of the filesystem encoding
Python runtime state: core initialized
Fatal Python error: init_fs_encoding: failed to get the Python codec of the filesystem encoding
Python runtime state: core initialized
Python path configuration:
Traceback (most recent call last):
  PYTHONHOME = (not set)
  PYTHONPATH = '/apps/skl/software/GDAL/2.2.3/lib/python3.6/site-packages:/apps/skl/software/GEOS/3.6.2/lib/python3.6/site-packages'
  program name = 'python3.9'
  isolated = 0
  environment = 1
  user site = 1
  import site = 1
Traceback (most recent call last):
Traceback (most recent call last):
Traceback (most recent call last):
  File "<frozen importlib._bootstrap>", line 1007, in _find_and_load
Fatal Python error: init_fs_encoding: failed to get the Python codec of the filesystem encoding
Python runtime state: core initialized
  File "<frozen importlib._bootstrap>", line 982, in _find_and_load_unlocked
  sys._base_executable = '/hpcfs/users/a1670295/myconda/envs/gt/bin/python3.9'
Python path configuration:
  PYTHONHOME = (not set)
  PYTHONPATH = '/apps/skl/software/GDAL/2.2.3/lib/python3.6/site-packages:/apps/skl/software/GEOS/3.6.2/lib/python3.6/site-packages'
  program name = 'python3.9'
  isolated = 0
  environment = 1
  user site = 1
  import site = 1
  sys._base_executable = '/hpcfs/users/a1670295/myconda/envs/gt/bin/python3.9'
Python path configuration:
  PYTHONHOME = (not set)
  PYTHONPATH = '/apps/skl/software/GDAL/2.2.3/lib/python3.6/site-packages:/apps/skl/software/GEOS/3.6.2/lib/python3.6/site-packages'
  program name = 'python3.9'
  isolated = 0
  environment = 1
  user site = 1
  import site = 1
  sys._base_executable = '/hpcfs/users/a1670295/myconda/envs/gt/bin/python3.9'
  sys.base_prefix = '/hpcfs/users/a1670295/myconda/envs/gt'
  sys.base_exec_prefix = '/hpcfs/users/a1670295/myconda/envs/gt'
  sys.platlibdir = 'lib'
  sys.executable = '/hpcfs/users/a1670295/myconda/envs/gt/bin/python3.9'
  sys.prefix = '/hpcfs/users/a1670295/myconda/envs/gt'
  sys.exec_prefix = '/hpcfs/users/a1670295/myconda/envs/gt'
  sys.path = [
    '/apps/skl/software/GDAL/2.2.3/lib/python3.6/site-packages',
    '/apps/skl/software/GEOS/3.6.2/lib/python3.6/site-packages',
    '/hpcfs/users/a1670295/myconda/envs/gt/lib/python39.zip',
    '/hpcfs/users/a1670295/myconda/envs/gt/lib/python3.9',
    '/hpcfs/users/a1670295/myconda/envs/gt/lib/python3.9/lib-dynload',
  ]
Fatal Python error: init_fs_encoding: Traceback (most recent call last):
failed to get the Python codec of the filesystem encoding
  sys.base_prefix = '/hpcfs/users/a1670295/myconda/envs/gt'
  sys.base_exec_prefix = '/hpcfs/users/a1670295/myconda/envs/gt'
  sys.platlibdir = 'lib'
  sys.executable = '/hpcfs/users/a1670295/myconda/envs/gt/bin/python3.9'
  sys.prefix = '/hpcfs/users/a1670295/myconda/envs/gt'
  sys.exec_prefix = '/hpcfs/users/a1670295/myconda/envs/gt'
  sys.path = [
    '/apps/skl/software/GDAL/2.2.3/lib/python3.6/site-packages',
    '/apps/skl/software/GEOS/3.6.2/lib/python3.6/site-packages',
    '/hpcfs/users/a1670295/myconda/envs/gt/lib/python39.zip',
    '/hpcfs/users/a1670295/myconda/envs/gt/lib/python3.9',
    '/hpcfs/users/a1670295/myconda/envs/gt/lib/python3.9/lib-dynload',
  ]
Fatal Python error: init_fs_encoding: failed to get the Python codec of the filesystem encoding
  sys.base_prefix = '/hpcfs/users/a1670295/myconda/envs/gt'
  sys.base_exec_prefix = '/hpcfs/users/a1670295/myconda/envs/gt'
  sys.platlibdir = 'lib'
  sys.executable = '/hpcfs/users/a1670295/myconda/envs/gt/bin/python3.9'
  sys.prefix = '/hpcfs/users/a1670295/myconda/envs/gt'
  sys.exec_prefix = '/hpcfs/users/a1670295/myconda/envs/gt'
  sys.path = [
    '/apps/skl/software/GDAL/2.2.3/lib/python3.6/site-packages',
    '/apps/skl/software/GEOS/3.6.2/lib/python3.6/site-packages',
    '/hpcfs/users/a1670295/myconda/envs/gt/lib/python39.zip',
    '/hpcfs/users/a1670295/myconda/envs/gt/lib/python3.9',
    '/hpcfs/users/a1670295/myconda/envs/gt/lib/python3.9/lib-dynload',
  ]
Fatal Python error: init_fs_encoding: failed to get the Python codec of the filesystem encoding
  File "<frozen importlib._bootstrap>", line 1007, in _find_and_load
Python runtime state: core initialized
Python runtime state: core initialized
Python runtime state: core initialized
  File "<frozen importlib._bootstrap>", line 1007, in _find_and_load
Traceback (most recent call last):
  File "/hpcfs/users/a1670295/Sampling/Python/phoenix_tree_dist.py", line 1, in <module>
  File "/hpcfs/users/a1670295/myconda/envs/gt/lib/python3.9/site-packages/jedi/api/__init__.py", line 22, in <module>
Traceback (most recent call last):
  File "<frozen importlib._bootstrap>", line 1007, in _find_and_load
Traceback (most recent call last):
  File "<frozen importlib._bootstrap>", line 1007, in _find_and_load
Python path configuration:
  PYTHONHOME = (not set)
  PYTHONPATH = '/apps/skl/software/GDAL/2.2.3/lib/python3.6/site-packages:/apps/skl/software/GEOS/3.6.2/lib/python3.6/site-packages'
  program name = 'python3.9'
  isolated = 0
  environment = 1
  user site = 1
  import site = 1
  sys._base_executable = '/hpcfs/users/a1670295/myconda/envs/gt/bin/python3.9'
  sys.base_prefix = '/hpcfs/users/a1670295/myconda/envs/gt'
  sys.base_exec_prefix = '/hpcfs/users/a1670295/myconda/envs/gt'
  sys.platlibdir = 'lib'
  sys.executable = '/hpcfs/users/a1670295/myconda/envs/gt/bin/python3.9'
  sys.prefix = '/hpcfs/users/a1670295/myconda/envs/gt'
  sys.exec_prefix = '/hpcfs/users/a1670295/myconda/envs/gt'
  sys.path = [
    '/apps/skl/software/GDAL/2.2.3/lib/python3.6/site-packages',
    '/apps/skl/software/GEOS/3.6.2/lib/python3.6/site-packages',
    '/hpcfs/users/a1670295/myconda/envs/gt/lib/python39.zip',
    '/hpcfs/users/a1670295/myconda/envs/gt/lib/python3.9',
    '/hpcfs/users/a1670295/myconda/envs/gt/lib/python3.9/lib-dynload',
  ]
Fatal Python error: init_fs_encoding: Traceback (most recent call last):
  File "/hpcfs/users/a1670295/myconda/envs/gt/lib/python3.9/site-packages/numpy/compat/py3k.py", line 28, in <module>
failed to get the Python codec of the filesystem encoding
Python runtime state: core initialized
Traceback (most recent call last):
  File "<frozen importlib._bootstrap>", line 1007, in _find_and_load
    import pickle5 as pickle
ModuleNotFoundError: No module named 'pickle5'

During handling of the above exception, another exception occurred:

Traceback (most recent call last):
  File "/hpcfs/users/a1670295/Sampling/Python/phoenix_tree_dist.py", line 1, in <module>
    import pandas as pd
  File "<frozen importlib._bootstrap>", line 1007, in _find_and_load
  File "<frozen importlib._bootstrap>", line 982, in _find_and_load_unlocked
  File "<frozen importlib._bootstrap>", line 925, in _find_spec
  File "<frozen importlib._bootstrap_external>", line 1349, in find_spec
  File "<frozen importlib._bootstrap_external>", line 1321, in _get_spec
  File "<frozen importlib._bootstrap_external>", line 1450, in find_spec
  File "<frozen importlib._bootstrap_external>", line 1490, in _fill_cache
  File "<frozen importlib._bootstrap>", line 982, in _find_and_load_unlocked
  File "<frozen importlib._bootstrap>", line 925, in _find_spec
  File "<frozen importlib._bootstrap_external>", line 1349, in find_spec
  File "<frozen importlib._bootstrap_external>", line 1321, in _get_spec
  File "<frozen importlib._bootstrap_external>", line 1450, in find_spec
  File "<frozen importlib._bootstrap_external>", line 1490, in _fill_cache
OSError: [Errno 12] Cannot allocate memory: '/hpcfs/users/a1670295/myconda/envs/gt/lib/python3.9'
OSError: [Errno 12] Cannot allocate memory: '/hpcfs/users/a1670295/Sampling/Python'
  File "<frozen importlib._bootstrap>", line 982, in _find_and_load_unlocked
  File "<frozen importlib._bootstrap>", line 925, in _find_spec
  File "<frozen importlib._bootstrap_external>", line 1349, in find_spec
  File "<frozen importlib._bootstrap_external>", line 1321, in _get_spec
  File "<frozen importlib._bootstrap_external>", line 1450, in find_spec
  File "<frozen importlib._bootstrap_external>", line 1490, in _fill_cache
OSError: [Errno 12] Cannot allocate memory: '/hpcfs/users/a1670295/myconda/envs/gt/lib/python3.9'
    from jedi.api import classes
  File "/hpcfs/users/a1670295/myconda/envs/gt/lib/python3.9/site-packages/jedi/api/classes.py", line 24, in <module>
    from jedi.inference.utils import unite
  File "/hpcfs/users/a1670295/myconda/envs/gt/lib/python3.9/site-packages/jedi/inference/__init__.py", line 70, in <module>
    from jedi.inference import imports
  File "/hpcfs/users/a1670295/myconda/envs/gt/lib/python3.9/site-packages/jedi/inference/imports.py", line 31, in <module>
    from jedi.inference.compiled.subprocess.functions import ImplicitNSInfo
  File "/hpcfs/users/a1670295/myconda/envs/gt/lib/python3.9/site-packages/jedi/inference/compiled/subprocess/__init__.py", line 25, in <module>
  File "<frozen importlib._bootstrap>", line 982, in _find_and_load_unlocked
  File "<frozen importlib._bootstrap>", line 925, in _find_spec
  File "<frozen importlib._bootstrap_external>", line 1349, in find_spec
  File "<frozen importlib._bootstrap_external>", line 1321, in _get_spec
  File "<frozen importlib._bootstrap_external>", line 1450, in find_spec
  File "<frozen importlib._bootstrap_external>", line 1490, in _fill_cache
OSError: [Errno 12] Cannot allocate memory: '/hpcfs/users/a1670295/myconda/envs/gt/lib/python3.9'
  File "<frozen importlib._bootstrap>", line 982, in _find_and_load_unlocked
  File "<frozen importlib._bootstrap>", line 925, in _find_spec
  File "<frozen importlib._bootstrap_external>", line 1349, in find_spec
  File "<frozen importlib._bootstrap_external>", line 1321, in _get_spec
  File "<frozen importlib._bootstrap_external>", line 1450, in find_spec
  File "<frozen importlib._bootstrap_external>", line 1490, in _fill_cache
OSError: [Errno 12] Cannot allocate memory: '/hpcfs/users/a1670295/myconda/envs/gt/lib/python3.9'
    from jedi.api.exceptions import InternalError
  File "<frozen importlib._bootstrap>", line 1007, in _find_and_load
  File "<frozen importlib._bootstrap>", line 986, in _find_and_load_unlocked
  File "<frozen importlib._bootstrap>", line 680, in _load_unlocked
  File "<frozen importlib._bootstrap_external>", line 786, in exec_module
  File "<frozen importlib._bootstrap_external>", line 922, in get_code
  File "<frozen importlib._bootstrap_external>", line 980, in get_data
OSError: [Errno 12] Cannot allocate memory
Python path configuration:
  PYTHONHOME = (not set)
  PYTHONPATH = '/apps/skl/software/GDAL/2.2.3/lib/python3.6/site-packages:/apps/skl/software/GEOS/3.6.2/lib/python3.6/site-packages'
  program name = 'python3.9'
  isolated = 0
  environment = 1
  user site = 1
  import site = 1
  sys._base_executable = '/hpcfs/users/a1670295/myconda/envs/gt/bin/python3.9'
  sys.base_prefix = '/hpcfs/users/a1670295/myconda/envs/gt'
  sys.base_exec_prefix = '/hpcfs/users/a1670295/myconda/envs/gt'
  sys.platlibdir = 'lib'
  sys.executable = '/hpcfs/users/a1670295/myconda/envs/gt/bin/python3.9'
  sys.prefix = '/hpcfs/users/a1670295/myconda/envs/gt'
  sys.exec_prefix = '/hpcfs/users/a1670295/myconda/envs/gt'
  sys.path = [
    '/apps/skl/software/GDAL/2.2.3/lib/python3.6/site-packages',
    '/apps/skl/software/GEOS/3.6.2/lib/python3.6/site-packages',
    '/hpcfs/users/a1670295/myconda/envs/gt/lib/python39.zip',
    '/hpcfs/users/a1670295/myconda/envs/gt/lib/python3.9',
    '/hpcfs/users/a1670295/myconda/envs/gt/lib/python3.9/lib-dynload',
  ]
Fatal Python error: init_fs_encoding: failed to get the Python codec of the filesystem encoding
Python runtime state: core initialized
Traceback (most recent call last):
    known_paths = addsitepackages(known_paths)
  File "/hpcfs/users/a1670295/myconda/envs/gt/lib/python3.9/site.py", line 359, in addsitepackages
    addsitedir(sitedir, known_paths)
  File "/hpcfs/users/a1670295/myconda/envs/gt/lib/python3.9/site.py", line 208, in addsitedir
  File "<frozen importlib._bootstrap>", line 1007, in _find_and_load
    addpackage(sitedir, name, known_paths)
  File "/hpcfs/users/a1670295/myconda/envs/gt/lib/python3.9/site.py", line 164, in addpackage
    for n, line in enumerate(f):
OSError: [Errno 12] Cannot allocate memory
    import pandas as pd
  File "/hpcfs/users/a1670295/myconda/envs/gt/lib/python3.9/site-packages/pandas/__init__.py", line 11, in <module>
    from .debugger import TerminalPdb, Pdb
  File "/hpcfs/users/a1670295/myconda/envs/gt/lib/python3.9/site-packages/IPython/terminal/debugger.py", line 8, in <module>
    __import__(dependency)
  File "/hpcfs/users/a1670295/myconda/envs/gt/lib/python3.9/site-packages/numpy/__init__.py", line 145, in <module>
    from IPython.core.completer import IPCompleter
  File "/hpcfs/users/a1670295/myconda/envs/gt/lib/python3.9/site-packages/IPython/core/completer.py", line 146, in <module>
    import jedi
  File "/hpcfs/users/a1670295/myconda/envs/gt/lib/python3.9/site-packages/jedi/__init__.py", line 32, in <module>
    from jedi.api import Script, Interpreter, set_debug_function, preload_module
  File "/hpcfs/users/a1670295/myconda/envs/gt/lib/python3.9/site-packages/jedi/api/__init__.py", line 22, in <module>
    from jedi.api import classes
  File "/hpcfs/users/a1670295/myconda/envs/gt/lib/python3.9/site-packages/jedi/api/classes.py", line 32, in <module>
    from . import core
  File "/hpcfs/users/a1670295/myconda/envs/gt/lib/python3.9/site-packages/numpy/core/__init__.py", line 22, in <module>
    from jedi.api import completion_cache
  File "<frozen importlib._bootstrap>", line 1007, in _find_and_load
  File "<frozen importlib._bootstrap>", line 986, in _find_and_load_unlocked
  File "<frozen importlib._bootstrap>", line 680, in _load_unlocked
  File "<frozen importlib._bootstrap_external>", line 786, in exec_module
  File "<frozen importlib._bootstrap_external>", line 922, in get_code
  File "<frozen importlib._bootstrap_external>", line 980, in get_data
OSError: [Errno 12] Cannot allocate memory
    from . import multiarray
  File "/hpcfs/users/a1670295/myconda/envs/gt/lib/python3.9/site-packages/numpy/core/multiarray.py", line 12, in <module>
    from . import overrides
  File "/hpcfs/users/a1670295/myconda/envs/gt/lib/python3.9/site-packages/numpy/core/overrides.py", line 9, in <module>
    from numpy.compat._inspect import getargspec
  File "/hpcfs/users/a1670295/myconda/envs/gt/lib/python3.9/site-packages/numpy/compat/__init__.py", line 12, in <module>
    from . import py3k
  File "/hpcfs/users/a1670295/myconda/envs/gt/lib/python3.9/site-packages/numpy/compat/py3k.py", line 30, in <module>
    import pickle
  File "/hpcfs/users/a1670295/myconda/envs/gt/lib/python3.9/pickle.py", line 37, in <module>
    import _compat_pickle
  File "<frozen importlib._bootstrap>", line 1007, in _find_and_load
  File "<frozen importlib._bootstrap>", line 986, in _find_and_load_unlocked
  File "<frozen importlib._bootstrap>", line 680, in _load_unlocked
  File "<frozen importlib._bootstrap_external>", line 786, in exec_module
  File "<frozen importlib._bootstrap_external>", line 922, in get_code
  File "<frozen importlib._bootstrap_external>", line 980, in get_data
OSError: [Errno 12] Cannot allocate memory
  File "<frozen importlib._bootstrap>", line 982, in _find_and_load_unlocked
  File "<frozen importlib._bootstrap>", line 925, in _find_spec
  File "<frozen importlib._bootstrap_external>", line 1349, in find_spec
  File "<frozen importlib._bootstrap_external>", line 1321, in _get_spec
  File "<frozen importlib._bootstrap_external>", line 1450, in find_spec
  File "<frozen importlib._bootstrap_external>", line 1490, in _fill_cache
OSError  File "<frozen importlib._bootstrap>", line 982, in _find_and_load_unlocked
  File "<frozen importlib._bootstrap>", line 925, in _find_spec
  File "<frozen importlib._bootstrap_external>", line 1349, in find_spec
  File "<frozen importlib._bootstrap_external>", line 1321, in _get_spec
  File "<frozen importlib._bootstrap_external>", line 1450, in find_spec
  File "<frozen importlib._bootstrap_external>", line 1490, in _fill_cache
OSError: [Errno 12] Cannot allocate memory: '/hpcfs/users/a1670295/myconda/envs/gt/lib/python3.9'
: [Errno 12] Cannot allocate memory: '/hpcfs/users/a1670295/myconda/envs/gt/lib/python3.9'
  File "<frozen importlib._bootstrap>", line 1007, in _find_and_load
  File "<frozen importlib._bootstrap>", line 1007, in _find_and_load
  File "<frozen importlib._bootstrap>", line 982, in _find_and_load_unlocked
  File "<frozen importlib._bootstrap>", line 925, in _find_spec
  File "<frozen importlib._bootstrap_external>", line 1349, in find_spec
  File "<frozen importlib._bootstrap_external>", line 1321, in _get_spec
  File "<frozen importlib._bootstrap_external>", line 1450, in find_spec
  File "<frozen importlib._bootstrap_external>", line 1490, in _fill_cache
OSError: [Errno 12] Cannot allocate memory: '/hpcfs/users/a1670295/myconda/envs/gt/lib/python3.9'
  File "<frozen importlib._bootstrap>", line 925, in _find_spec
  File "<frozen importlib._bootstrap>", line 982, in _find_and_load_unlocked
  File "<frozen importlib._bootstrap>", line 925, in _find_spec
  File "<frozen importlib._bootstrap_external>", line 1349, in find_spec
  File "<frozen importlib._bootstrap_external>", line 1321, in _get_spec
  File "<frozen importlib._bootstrap_external>", line 1450, in find_spec
  File "<frozen importlib._bootstrap_external>", line 1490, in _fill_cache
OSError: [Errno 12] Cannot allocate memory: '/hpcfs/users/a1670295/myconda/envs/gt/lib/python3.9'
  File "<frozen importlib._bootstrap_external>", line 1349, in find_spec
  File "<frozen importlib._bootstrap_external>", line 1321, in _get_spec
  File "<frozen importlib._bootstrap_external>", line 1450, in find_spec
  File "<frozen importlib._bootstrap_external>", line 1490, in _fill_cache
OSError: [Errno 12] Cannot allocate memory: '/apps/skl/software/GEOS/3.6.2/lib/python3.6/site-packages'
  File "<frozen importlib._bootstrap>", line 982, in _find_and_load_unlocked
  File "<frozen importlib._bootstrap>", line 925, in _find_spec
  File "<frozen importlib._bootstrap_external>", line 1349, in find_spec
  File "<frozen importlib._bootstrap_external>", line 1321, in _get_spec
  File "<frozen importlib._bootstrap_external>", line 1450, in find_spec
  File "<frozen importlib._bootstrap_external>", line 1490, in _fill_cache
OSError: [Errno 12] Cannot allocate memory: '/hpcfs/users/a1670295/myconda/envs/gt/lib/python3.9'
Traceback (most recent call last):
  File "/hpcfs/users/a1670295/Sampling/Python/phoenix_tree_dist.py", line 1, in <module>
    import pandas as pd
  File "/hpcfs/users/a1670295/myconda/envs/gt/lib/python3.9/site-packages/pandas/__init__.py", line 11, in <module>
Error processing line 1 of /hpcfs/users/a1670295/myconda/envs/gt/lib/python3.9/site-packages/matplotlib-3.3.4-py3.9-nspkg.pth:

    __import__(dependency)
  File "/hpcfs/users/a1670295/myconda/envs/gt/lib/python3.9/site-packages/numpy/__init__.py", line 145, in <module>
  File "/hpcfs/users/a1670295/myconda/envs/gt/lib/python3.9/site-packages/prompt_toolkit/clipboard/__init__.py", line 1, in <module>
    from .base import Clipboard, ClipboardData, DummyClipboard, DynamicClipboard
  File "<frozen importlib._bootstrap>", line 1007, in _find_and_load
  File "<frozen importlib._bootstrap>", line 986, in _find_and_load_unlocked
  File "<frozen importlib._bootstrap>", line 680, in _load_unlocked
  File "<frozen importlib._bootstrap_external>", line 786, in exec_module
  File "<frozen importlib._bootstrap_external>", line 922, in get_code
  File "<frozen importlib._bootstrap_external>", line 980, in get_data
OSError: [Errno 12] Cannot allocate memory
    from . import core
  File "/hpcfs/users/a1670295/myconda/envs/gt/lib/python3.9/site-packages/numpy/core/__init__.py", line 22, in <module>
    from . import multiarray
  File "/hpcfs/users/a1670295/myconda/envs/gt/lib/python3.9/site-packages/numpy/core/multiarray.py", line 12, in <module>
    from . import overrides
  File "/hpcfs/users/a1670295/myconda/envs/gt/lib/python3.9/site-packages/numpy/core/overrides.py", line 9, in <module>
    from numpy.compat._inspect import getargspec
  File "/hpcfs/users/a1670295/myconda/envs/gt/lib/python3.9/site-packages/numpy/compat/__init__.py", line 11, in <module>
    from . import _inspect
  File "<frozen importlib._bootstrap>", line 1007, in _find_and_load
  File "<frozen importlib._bootstrap>", line 982, in _find_and_load_unlocked
  File "<frozen importlib._bootstrap>", line 925, in _find_spec
  File "<frozen importlib._bootstrap_external>", line 1349, in find_spec
  File "<frozen importlib._bootstrap_external>", line 1321, in _get_spec
  File "<frozen importlib._bootstrap_external>", line 1450, in find_spec
  File "<frozen importlib._bootstrap_external>", line 1490, in _fill_cache
OSError: [Errno 12] Cannot allocate memory: '/hpcfs/users/a1670295/myconda/envs/gt/lib/python3.9/site-packages/numpy/compat'
Traceback (most recent call last):
  File "/hpcfs/users/a1670295/Sampling/Python/phoenix_tree_dist.py", line 1, in <module>
    import pandas as pd
  File "/hpcfs/users/a1670295/myconda/envs/gt/lib/python3.9/site-packages/pandas/__init__.py", line 16, in <module>
Traceback (most recent call last):
  File "/hpcfs/users/a1670295/Sampling/Python/phoenix_tree_dist.py", line 1, in <module>
    import pandas as pd
  File "/hpcfs/users/a1670295/myconda/envs/gt/lib/python3.9/site-packages/pandas/__init__.py", line 11, in <module>
    __import__(dependency)
  File "/hpcfs/users/a1670295/myconda/envs/gt/lib/python3.9/site-packages/numpy/__init__.py", line 145, in <module>
    from . import core
  File "/hpcfs/users/a1670295/myconda/envs/gt/lib/python3.9/site-packages/numpy/core/__init__.py", line 76, in <module>
    from . import defchararray as char
  File "<frozen importlib._bootstrap>", line 1007, in _find_and_load
  File "<frozen importlib._bootstrap>", line 986, in _find_and_load_unlocked
  File "<frozen importlib._bootstrap>", line 680, in _load_unlocked
  File "<frozen importlib._bootstrap_external>", line 786, in exec_module
  File "<frozen importlib._bootstrap_external>", line 922, in get_code
  File "<frozen importlib._bootstrap_external>", line 980, in get_data
OSError: [Errno 12] Cannot allocate memory
    raise ImportError(
ImportError: Unable to import required dependencies:
numpy: 

IMPORTANT: PLEASE READ THIS FOR ADVICE ON HOW TO SOLVE THIS ISSUE!

Importing the numpy C-extensions failed. This error can happen for
many reasons, often due to issues with your setup or how NumPy was
installed.

We have compiled some common reasons and troubleshooting tips at:

    https://numpy.org/devdocs/user/troubleshooting-importerror.html

Please note and check the following:

  * The Python version is: Python3.9 from "/hpcfs/users/a1670295/myconda/envs/gt/bin/python3.9"
  * The NumPy version is: "1.20.3"

and make sure that they are the versions you expect.
Please carefully study the documentation linked above for further help.

Original error was: /hpcfs/users/a1670295/myconda/envs/gt/lib/python3.9/site-packages/numpy/core/_multiarray_umath.cpython-39-x86_64-linux-gnu.so: cannot read file data: Cannot allocate memory

Error processing line 1 of /hpcfs/users/a1670295/myconda/envs/gt/lib/python3.9/site-packages/matplotlib-3.3.4-py3.9-nspkg.pth:

Traceback (most recent call last):
  File "/hpcfs/users/a1670295/Sampling/Python/phoenix_tree_dist.py", line 1, in <module>
    import pandas as pd
  File "/hpcfs/users/a1670295/myconda/envs/gt/lib/python3.9/site-packages/pandas/__init__.py", line 16, in <module>
    raise ImportError(
ImportError: Unable to import required dependencies:
numpy: 

IMPORTANT: PLEASE READ THIS FOR ADVICE ON HOW TO SOLVE THIS ISSUE!

Importing the numpy C-extensions failed. This error can happen for
many reasons, often due to issues with your setup or how NumPy was
installed.

We have compiled some common reasons and troubleshooting tips at:

    https://numpy.org/devdocs/user/troubleshooting-importerror.html

Please note and check the following:

  * The Python version is: Python3.9 from "/hpcfs/users/a1670295/myconda/envs/gt/bin/python3.9"
  * The NumPy version is: "1.20.3"

and make sure that they are the versions you expect.
Please carefully study the documentation linked above for further help.

Original error was: /hpcfs/users/a1670295/myconda/envs/gt/lib/python3.9/site-packages/numpy/core/../../../.././libgfortran.so.5: cannot read file data: Cannot allocate memory

Traceback (most recent call last):
  File "/hpcfs/users/a1670295/Sampling/Python/phoenix_tree_dist.py", line 1, in <module>
    import pandas as pd
  File "/hpcfs/users/a1670295/myconda/envs/gt/lib/python3.9/site-packages/pandas/__init__.py", line 11, in <module>
    __import__(dependency)
  File "/hpcfs/users/a1670295/myconda/envs/gt/lib/python3.9/site-packages/numpy/__init__.py", line 145, in <module>
    from . import core
  File "/hpcfs/users/a1670295/myconda/envs/gt/lib/python3.9/site-packages/numpy/core/__init__.py", line 72, in <module>
    from . import numeric
  File "/hpcfs/users/a1670295/myconda/envs/gt/lib/python3.9/site-packages/numpy/core/numeric.py", line 23, in <module>
    from . import shape_base
  File "/hpcfs/users/a1670295/myconda/envs/gt/lib/python3.9/site-packages/numpy/core/shape_base.py", line 13, in <module>
    from . import fromnumeric as _from_nx
  File "<frozen importlib._bootstrap>", line 1007, in _find_and_load
  File "<frozen importlib._bootstrap>", line 986, in _find_and_load_unlocked
  File "<frozen importlib._bootstrap>", line 680, in _load_unlocked
  File "<frozen importlib._bootstrap_external>", line 786, in exec_module
  File "<frozen importlib._bootstrap_external>", line 922, in get_code
  File "<frozen importlib._bootstrap_external>", line 980, in get_data
OSError: [Errno 12] Cannot allocate memory
Traceback (most recent call last):
  File "<frozen importlib._bootstrap>", line 1007, in _find_and_load
  File "<frozen importlib._bootstrap>", line 982, in _find_and_load_unlocked
  File "<frozen importlib._bootstrap>", line 925, in _find_spec
  File "<frozen importlib._bootstrap_external>", line 1349, in find_spec
  File "<frozen importlib._bootstrap_external>", line 1321, in _get_spec
  File "<frozen importlib._bootstrap_external>", line 1450, in find_spec
  File "<frozen importlib._bootstrap_external>", line 1490, in _fill_cache
OSError: [Errno 12] Cannot allocate memory: '/hpcfs/users/a1670295/myconda/envs/gt/lib/python3.9'
  Traceback (most recent call last):
    File "/hpcfs/users/a1670295/myconda/envs/gt/lib/python3.9/site.py", line 169, in addpackage
      exec(line)
    File "<string>", line 1, in <module>
    File "<frozen importlib._bootstrap>", line 1007, in _find_and_load
    File "<frozen importlib._bootstrap>", line 986, in _find_and_load_unlocked
    File "<frozen importlib._bootstrap>", line 680, in _load_unlocked
    File "<frozen importlib._bootstrap_external>", line 786, in exec_module
    File "<frozen importlib._bootstrap_external>", line 922, in get_code
    File "<frozen importlib._bootstrap_external>", line 980, in get_data
  OSError: [Errno 12] Cannot allocate memory

Remainder of file ignored
/hpcfs/users/a1670295/myconda/envs/gt/lib/python3.9/site-packages/graph_tool/draw/cairo_draw.py:1501: RuntimeWarning: Error importing Gtk module: /hpcfs/users/a1670295/myconda/envs/gt/lib/python3.9/site-packages/gi/../../../libglib-2.0.so.0: cannot read file data: Cannot allocate memory; GTK+ drawing will not work.
  warnings.warn(msg, RuntimeWarning)
  Traceback (most recent call last):
    File "/hpcfs/users/a1670295/myconda/envs/gt/lib/python3.9/site.py", line 169, in addpackage
      exec(line)
    File "<string>", line 1, in <module>
    File "/hpcfs/users/a1670295/myconda/envs/gt/lib/python3.9/importlib/util.py", line 2, in <module>
      from . import abc
    File "/hpcfs/users/a1670295/myconda/envs/gt/lib/python3.9/importlib/abc.py", line 17, in <module>
      from typing import Protocol, runtime_checkable
    File "/hpcfs/users/a1670295/myconda/envs/gt/lib/python3.9/typing.py", line 22, in <module>
      import collections.abc
    File "<frozen importlib._bootstrap>", line 1007, in _find_and_load
    File "<frozen importlib._bootstrap>", line 986, in _find_and_load_unlocked
    File "<frozen importlib._bootstrap>", line 680, in _load_unlocked
    File "<frozen importlib._bootstrap_external>", line 786, in exec_module
    File "<frozen importlib._bootstrap_external>", line 922, in get_code
    File "<frozen importlib._bootstrap_external>", line 980, in get_data
  OSError: [Errno 12] Cannot allocate memory

Remainder of file ignored
Traceback (most recent call last):
  File "/hpcfs/users/a1670295/Sampling/Python/phoenix_tree_dist.py", line 1, in <module>
    import pandas as pd
  File "/hpcfs/users/a1670295/myconda/envs/gt/lib/python3.9/site-packages/pandas/__init__.py", line 11, in <module>
    __import__(dependency)
  File "/hpcfs/users/a1670295/myconda/envs/gt/lib/python3.9/site-packages/numpy/__init__.py", line 148, in <module>
    from . import lib
  File "<frozen importlib._bootstrap>", line 1007, in _find_and_load
  File "<frozen importlib._bootstrap>", line 986, in _find_and_load_unlocked
  File "<frozen importlib._bootstrap>", line 680, in _load_unlocked
  File "<frozen importlib._bootstrap_external>", line 786, in exec_module
  File "<frozen importlib._bootstrap_external>", line 922, in get_code
  File "<frozen importlib._bootstrap_external>", line 980, in get_data
OSError: [Errno 12] Cannot allocate memory
Traceback (most recent call last):
  File "/hpcfs/users/a1670295/Sampling/Python/phoenix_tree_dist.py", line 1, in <module>
    import pandas as pd
  File "/hpcfs/users/a1670295/myconda/envs/gt/lib/python3.9/site-packages/pandas/__init__.py", line 11, in <module>
Error processing line 1 of /hpcfs/users/a1670295/myconda/envs/gt/lib/python3.9/site-packages/matplotlib-3.3.4-py3.9-nspkg.pth:

    __import__(dependency)
  File "/hpcfs/users/a1670295/myconda/envs/gt/lib/python3.9/site-packages/numpy/__init__.py", line 145, in <module>
    from . import core
  File "/hpcfs/users/a1670295/myconda/envs/gt/lib/python3.9/site-packages/numpy/core/__init__.py", line 72, in <module>
    from . import numeric
  File "/hpcfs/users/a1670295/myconda/envs/gt/lib/python3.9/site-packages/numpy/core/numeric.py", line 30, in <module>
    from ._ufunc_config import errstate
  File "<frozen importlib._bootstrap>", line 1007, in _find_and_load
  File "<frozen importlib._bootstrap>", line 986, in _find_and_load_unlocked
  File "<frozen importlib._bootstrap>", line 680, in _load_unlocked
  File "<frozen importlib._bootstrap_external>", line 786, in exec_module
  File "<frozen importlib._bootstrap_external>", line 922, in get_code
  File "<frozen importlib._bootstrap_external>", line 980, in get_data
OSError: [Errno 12] Cannot allocate memory
Traceback (most recent call last):
  File "/hpcfs/users/a1670295/Sampling/Python/phoenix_tree_dist.py", line 1, in <module>
    import pandas as pd
  File "/hpcfs/users/a1670295/myconda/envs/gt/lib/python3.9/site-packages/pandas/__init__.py", line 11, in <module>
    __import__(dependency)
  File "/hpcfs/users/a1670295/myconda/envs/gt/lib/python3.9/site-packages/numpy/__init__.py", line 148, in <module>
    from . import lib
  File "<frozen importlib._bootstrap>", line 1007, in _find_and_load
  File "<frozen importlib._bootstrap>", line 986, in _find_and_load_unlocked
  File "<frozen importlib._bootstrap>", line 680, in _load_unlocked
  File "<frozen importlib._bootstrap_external>", line 786, in exec_module
  File "<frozen importlib._bootstrap_external>", line 922, in get_code
  File "<frozen importlib._bootstrap_external>", line 980, in get_data
OSError: [Errno 12] Cannot allocate memory
Traceback (most recent call last):
  File "/hpcfs/users/a1670295/Sampling/Python/phoenix_tree_dist.py", line 1, in <module>
Traceback (most recent call last):
  File "/hpcfs/users/a1670295/Sampling/Python/phoenix_tree_dist.py", line 1, in <module>
Traceback (most recent call last):
  File "/hpcfs/users/a1670295/Sampling/Python/phoenix_tree_dist.py", line 1, in <module>
    import pandas as pd
  File "/hpcfs/users/a1670295/myconda/envs/gt/lib/python3.9/site-packages/pandas/__init__.py", line 11, in <module>
    import pandas as pd
  File "/hpcfs/users/a1670295/myconda/envs/gt/lib/python3.9/site-packages/pandas/__init__.py", line 11, in <module>
    __import__(dependency)
  File "/hpcfs/users/a1670295/myconda/envs/gt/lib/python3.9/site-packages/numpy/__init__.py", line 145, in <module>
    __import__(dependency)
  File "/hpcfs/users/a1670295/myconda/envs/gt/lib/python3.9/site-packages/numpy/__init__.py", line 145, in <module>
    from . import core
  File "/hpcfs/users/a1670295/myconda/envs/gt/lib/python3.9/site-packages/numpy/core/__init__.py", line 102, in <module>
    from . import core
  File "/hpcfs/users/a1670295/myconda/envs/gt/lib/python3.9/site-packages/numpy/core/__init__.py", line 81, in <module>
    from . import function_base
  File "<frozen importlib._bootstrap>", line 1007, in _find_and_load
  File "<frozen importlib._bootstrap>", line 986, in _find_and_load_unlocked
  File "<frozen importlib._bootstrap>", line 680, in _load_unlocked
  File "<frozen importlib._bootstrap_external>", line 786, in exec_module
  File "<frozen importlib._bootstrap_external>", line 922, in get_code
  File "<frozen importlib._bootstrap_external>", line 980, in get_data
OSError: [Errno 12] Cannot allocate memory
    from . import _internal
  File "/hpcfs/users/a1670295/myconda/envs/gt/lib/python3.9/site-packages/numpy/core/_internal.py", line 10, in <module>
    import platform
  File "/hpcfs/users/a1670295/myconda/envs/gt/lib/python3.9/platform.py", line 119, in <module>
    import subprocess
  File "/hpcfs/users/a1670295/myconda/envs/gt/lib/python3.9/subprocess.py", line 49, in <module>
    import signal
  File "<frozen importlib._bootstrap>", line 1007, in _find_and_load
  File "<frozen importlib._bootstrap>", line 986, in _find_and_load_unlocked
  File "<frozen importlib._bootstrap>", line 680, in _load_unlocked
  File "<frozen importlib._bootstrap_external>", line 786, in exec_module
  File "<frozen importlib._bootstrap_external>", line 922, in get_code
  File "<frozen importlib._bootstrap_external>", line 980, in get_data
OSError: [Errno 12] Cannot allocate memory
    import pandas as pd
  File "/hpcfs/users/a1670295/myconda/envs/gt/lib/python3.9/site-packages/pandas/__init__.py", line 11, in <module>
    __import__(dependency)
  File "/hpcfs/users/a1670295/myconda/envs/gt/lib/python3.9/site-packages/numpy/__init__.py", line 145, in <module>
    from . import core
  File "/hpcfs/users/a1670295/myconda/envs/gt/lib/python3.9/site-packages/numpy/core/__init__.py", line 81, in <module>
    from . import function_base
  File "<frozen importlib._bootstrap>", line 1007, in _find_and_load
  File "<frozen importlib._bootstrap>", line 986, in _find_and_load_unlocked
  File "<frozen importlib._bootstrap>", line 680, in _load_unlocked
  File "<frozen importlib._bootstrap_external>", line 786, in exec_module
  File "<frozen importlib._bootstrap_external>", line 922, in get_code
  File "<frozen importlib._bootstrap_external>", line 980, in get_data
OSError: [Errno 12] Cannot allocate memory
Traceback (most recent call last):
  File "/hpcfs/users/a1670295/Sampling/Python/phoenix_tree_dist.py", line 1, in <module>
Traceback (most recent call last):
  File "/hpcfs/users/a1670295/Sampling/Python/phoenix_tree_dist.py", line 1, in <module>
    import pandas as pd
  File "/hpcfs/users/a1670295/myconda/envs/gt/lib/python3.9/site-packages/pandas/__init__.py", line 11, in <module>
    __import__(dependency)
  File "/hpcfs/users/a1670295/myconda/envs/gt/lib/python3.9/site-packages/numpy/__init__.py", line 148, in <module>
    import pandas as pd
  File "/hpcfs/users/a1670295/myconda/envs/gt/lib/python3.9/site-packages/pandas/__init__.py", line 11, in <module>
    from . import lib
  File "/hpcfs/users/a1670295/myconda/envs/gt/lib/python3.9/site-packages/numpy/lib/__init__.py", line 25, in <module>
    __import__(dependency)
  File "/hpcfs/users/a1670295/myconda/envs/gt/lib/python3.9/site-packages/numpy/__init__.py", line 148, in <module>
    from . import lib
  File "/hpcfs/users/a1670295/myconda/envs/gt/lib/python3.9/site-packages/numpy/lib/__init__.py", line 25, in <module>
    from .index_tricks import *
  File "/hpcfs/users/a1670295/myconda/envs/gt/lib/python3.9/site-packages/numpy/lib/index_tricks.py", line 12, in <module>
Traceback (most recent call last):
  File "/hpcfs/users/a1670295/Sampling/Python/phoenix_tree_dist.py", line 1, in <module>
    import pandas as pd
  File "/hpcfs/users/a1670295/myconda/envs/gt/lib/python3.9/site-packages/pandas/__init__.py", line 11, in <module>
    import numpy.matrixlib as matrixlib
  File "/hpcfs/users/a1670295/myconda/envs/gt/lib/python3.9/site-packages/numpy/matrixlib/__init__.py", line 4, in <module>
    from .index_tricks import *
  File "/hpcfs/users/a1670295/myconda/envs/gt/lib/python3.9/site-packages/numpy/lib/index_tricks.py", line 12, in <module>
    __import__(dependency)
  File "/hpcfs/users/a1670295/myconda/envs/gt/lib/python3.9/site-packages/numpy/__init__.py", line 145, in <module>
    import numpy.matrixlib as matrixlib
  File "/hpcfs/users/a1670295/myconda/envs/gt/lib/python3.9/site-packages/numpy/matrixlib/__init__.py", line 4, in <module>
    from .defmatrix import *
  File "/hpcfs/users/a1670295/myconda/envs/gt/lib/python3.9/site-packages/numpy/matrixlib/defmatrix.py", line 11, in <module>
Traceback (most recent call last):
  File "/hpcfs/users/a1670295/Sampling/Python/phoenix_tree_dist.py", line 1, in <module>
Traceback (most recent call last):
  File "/hpcfs/users/a1670295/Sampling/Python/phoenix_tree_dist.py", line 1, in <module>
    from .defmatrix import *
  File "/hpcfs/users/a1670295/myconda/envs/gt/lib/python3.9/site-packages/numpy/matrixlib/defmatrix.py", line 11, in <module>
    import pandas as pd
  File "/hpcfs/users/a1670295/myconda/envs/gt/lib/python3.9/site-packages/pandas/__init__.py", line 11, in <module>
    from . import core
  File "/hpcfs/users/a1670295/myconda/envs/gt/lib/python3.9/site-packages/numpy/core/__init__.py", line 77, in <module>
    import pandas as pd
  File "/hpcfs/users/a1670295/myconda/envs/gt/lib/python3.9/site-packages/pandas/__init__.py", line 11, in <module>
    __import__(dependency)
  File "/hpcfs/users/a1670295/myconda/envs/gt/lib/python3.9/site-packages/numpy/__init__.py", line 148, in <module>
    from . import lib
    from numpy.linalg import matrix_power
    from . import records as rec
    from numpy.linalg import matrix_power
  File "/hpcfs/users/a1670295/myconda/envs/gt/lib/python3.9/site-packages/numpy/lib/__init__.py", line 25, in <module>
  File "/hpcfs/users/a1670295/myconda/envs/gt/lib/python3.9/site-packages/numpy/linalg/__init__.py", line 73, in <module>
  File "<frozen importlib._bootstrap>", line 1007, in _find_and_load
  File "<frozen importlib._bootstrap>", line 1007, in _find_and_load
  File "<frozen importlib._bootstrap>", line 986, in _find_and_load_unlocked
  File "<frozen importlib._bootstrap>", line 680, in _load_unlocked
  File "<frozen importlib._bootstrap_external>", line 786, in exec_module
  File "<frozen importlib._bootstrap_external>", line 922, in get_code
  File "<frozen importlib._bootstrap_external>", line 980, in get_data
    from .linalg import *
  File "<frozen importlib._bootstrap>", line 1007, in _find_and_load
  File "<frozen importlib._bootstrap>", line 986, in _find_and_load_unlocked
  File "<frozen importlib._bootstrap>", line 680, in _load_unlocked
  File "<frozen importlib._bootstrap_external>", line 786, in exec_module
  File "<frozen importlib._bootstrap_external>", line 922, in get_code
  File "<frozen importlib._bootstrap_external>", line 980, in get_data
  File "<frozen importlib._bootstrap>", line 986, in _find_and_load_unlocked
  File "<frozen importlib._bootstrap>", line 680, in _load_unlocked
  File "<frozen importlib._bootstrap_external>", line 786, in exec_module
  File "<frozen importlib._bootstrap_external>", line 922, in get_code
  File "<frozen importlib._bootstrap_external>", line 980, in get_data
OSError: [Errno 12] Cannot allocate memory
OSError: [Errno 12] Cannot allocate memory
    from .index_tricks import *
  File "/hpcfs/users/a1670295/myconda/envs/gt/lib/python3.9/site-packages/numpy/lib/index_tricks.py", line 12, in <module>
OSError: [Errno 12] Cannot allocate memory
    import numpy.matrixlib as matrixlib
  File "/hpcfs/users/a1670295/myconda/envs/gt/lib/python3.9/site-packages/numpy/matrixlib/__init__.py", line 4, in <module>
    from .defmatrix import *
  File "/hpcfs/users/a1670295/myconda/envs/gt/lib/python3.9/site-packages/numpy/matrixlib/defmatrix.py", line 11, in <module>
    from numpy.linalg import matrix_power
  File "/hpcfs/users/a1670295/myconda/envs/gt/lib/python3.9/site-packages/numpy/linalg/__init__.py", line 73, in <module>
Traceback (most recent call last):
  File "/hpcfs/users/a1670295/Sampling/Python/phoenix_tree_dist.py", line 1, in <module>
    from .linalg import *
  File "<frozen importlib._bootstrap>", line 1007, in _find_and_load
  File "<frozen importlib._bootstrap>", line 986, in _find_and_load_unlocked
  File "<frozen importlib._bootstrap>", line 680, in _load_unlocked
  File "<frozen importlib._bootstrap_external>", line 786, in exec_module
  File "<frozen importlib._bootstrap_external>", line 922, in get_code
  File "<frozen importlib._bootstrap_external>", line 980, in get_data
    import pandas as pd
  File "/hpcfs/users/a1670295/myconda/envs/gt/lib/python3.9/site-packages/pandas/__init__.py", line 11, in <module>
OSError: [Errno 12] Cannot allocate memory
Traceback (most recent call last):
  File "/hpcfs/users/a1670295/Sampling/Python/phoenix_tree_dist.py", line 1, in <module>
Traceback (most recent call last):
  File "/hpcfs/users/a1670295/Sampling/Python/phoenix_tree_dist.py", line 1, in <module>
    __import__(dependency)
  File "/hpcfs/users/a1670295/myconda/envs/gt/lib/python3.9/site-packages/numpy/__init__.py", line 148, in <module>
    __import__(dependency)
  File "/hpcfs/users/a1670295/myconda/envs/gt/lib/python3.9/site-packages/numpy/__init__.py", line 112, in <module>
    import pandas as pd
  File "/hpcfs/users/a1670295/myconda/envs/gt/lib/python3.9/site-packages/pandas/__init__.py", line 11, in <module>
    from . import lib
  File "/hpcfs/users/a1670295/myconda/envs/gt/lib/python3.9/site-packages/numpy/lib/__init__.py", line 25, in <module>
    import pandas as pd
  File "/hpcfs/users/a1670295/myconda/envs/gt/lib/python3.9/site-packages/pandas/__init__.py", line 11, in <module>
    from ._globals import ModuleDeprecationWarning, VisibleDeprecationWarning
  File "<frozen importlib._bootstrap>", line 1007, in _find_and_load
  File "<frozen importlib._bootstrap>", line 982, in _find_and_load_unlocked
  File "<frozen importlib._bootstrap>", line 925, in _find_spec
  File "<frozen importlib._bootstrap_external>", line 1349, in find_spec
  File "<frozen importlib._bootstrap_external>", line 1321, in _get_spec
  File "<frozen importlib._bootstrap_external>", line 1450, in find_spec
  File "<frozen importlib._bootstrap_external>", line 1490, in _fill_cache
OSError: [Errno 12] Cannot allocate memory: '/hpcfs/users/a1670295/myconda/envs/gt/lib/python3.9/site-packages/numpy'
    __import__(dependency)
  File "/hpcfs/users/a1670295/myconda/envs/gt/lib/python3.9/site-packages/numpy/__init__.py", line 145, in <module>
    from . import core
  File "/hpcfs/users/a1670295/myconda/envs/gt/lib/python3.9/site-packages/numpy/core/__init__.py", line 102, in <module>
    from .index_tricks import *
  File "/hpcfs/users/a1670295/myconda/envs/gt/lib/python3.9/site-packages/numpy/lib/index_tricks.py", line 12, in <module>
    from . import _internal
  File "/hpcfs/users/a1670295/myconda/envs/gt/lib/python3.9/site-packages/numpy/core/_internal.py", line 10, in <module>
    import platform
  File "/hpcfs/users/a1670295/myconda/envs/gt/lib/python3.9/platform.py", line 119, in <module>
    import numpy.matrixlib as matrixlib
  File "/hpcfs/users/a1670295/myconda/envs/gt/lib/python3.9/site-packages/numpy/matrixlib/__init__.py", line 4, in <module>
    import subprocess
  File "/hpcfs/users/a1670295/myconda/envs/gt/lib/python3.9/subprocess.py", line 51, in <module>
    from .defmatrix import *
  File "/hpcfs/users/a1670295/myconda/envs/gt/lib/python3.9/site-packages/numpy/matrixlib/defmatrix.py", line 11, in <module>
    import threading
  File "/hpcfs/users/a1670295/myconda/envs/gt/lib/python3.9/threading.py", line 9, in <module>
    from numpy.linalg import matrix_power
  File "/hpcfs/users/a1670295/myconda/envs/gt/lib/python3.9/site-packages/numpy/linalg/__init__.py", line 73, in <module>
    from .linalg import *
  File "<frozen importlib._bootstrap>", line 1007, in _find_and_load
  File "<frozen importlib._bootstrap>", line 986, in _find_and_load_unlocked
  File "<frozen importlib._bootstrap>", line 680, in _load_unlocked
  File "<frozen importlib._bootstrap_external>", line 786, in exec_module
  File "<frozen importlib._bootstrap_external>", line 922, in get_code
  File "<frozen importlib._bootstrap_external>", line 980, in get_data
OSError: [Errno 12] Cannot allocate memory
    from _weakrefset import WeakSet
  File "<frozen importlib._bootstrap>", line 1007, in _find_and_load
  File "<frozen importlib._bootstrap>", line 986, in _find_and_load_unlocked
  File "<frozen importlib._bootstrap>", line 680, in _load_unlocked
  File "<frozen importlib._bootstrap_external>", line 786, in exec_module
  File "<frozen importlib._bootstrap_external>", line 922, in get_code
  File "<frozen importlib._bootstrap_external>", line 980, in get_data
OSError: [Errno 12] Cannot allocate memory
    __import__(dependency)
  File "/hpcfs/users/a1670295/myconda/envs/gt/lib/python3.9/site-packages/numpy/__init__.py", line 145, in <module>
    from . import core
  File "/hpcfs/users/a1670295/myconda/envs/gt/lib/python3.9/site-packages/numpy/core/__init__.py", line 22, in <module>
    from . import multiarray
  File "<frozen importlib._bootstrap>", line 1007, in _find_and_load
  File "<frozen importlib._bootstrap>", line 982, in _find_and_load_unlocked
  File "<frozen importlib._bootstrap>", line 925, in _find_spec
  File "<frozen importlib._bootstrap_external>", line 1349, in find_spec
  File "<frozen importlib._bootstrap_external>", line 1321, in _get_spec
  File "<frozen importlib._bootstrap_external>", line 1450, in find_spec
  File "<frozen importlib._bootstrap_external>", line 1490, in _fill_cache
OSError: [Errno 12] Cannot allocate memory: '/hpcfs/users/a1670295/myconda/envs/gt/lib/python3.9/site-packages/numpy/core'
  Traceback (most recent call last):
    File "/hpcfs/users/a1670295/myconda/envs/gt/lib/python3.9/site.py", line 169, in addpackage
      exec(line)
    File "<string>", line 1, in <module>
    File "/hpcfs/users/a1670295/myconda/envs/gt/lib/python3.9/importlib/util.py", line 2, in <module>
      from . import abc
    File "/hpcfs/users/a1670295/myconda/envs/gt/lib/python3.9/importlib/abc.py", line 17, in <module>
      from typing import Protocol, runtime_checkable
    File "/hpcfs/users/a1670295/myconda/envs/gt/lib/python3.9/typing.py", line 21, in <module>
      import collections
    File "/hpcfs/users/a1670295/myconda/envs/gt/lib/python3.9/collections/__init__.py", line 30, in <module>
      import heapq as _heapq
    File "<frozen importlib._bootstrap>", line 1007, in _find_and_load
    File "<frozen importlib._bootstrap>", line 986, in _find_and_load_unlocked
    File "<frozen importlib._bootstrap>", line 680, in _load_unlocked
    File "<frozen importlib._bootstrap_external>", line 786, in exec_module
    File "<frozen importlib._bootstrap_external>", line 922, in get_code
    File "<frozen importlib._bootstrap_external>", line 980, in get_data
  OSError: [Errno 12] Cannot allocate memory

Remainder of file ignored
    from jedi.inference import compiled
    from . cairo_draw import graph_draw, cairo_draw, \
Traceback (most recent call last):
  File "/hpcfs/users/a1670295/Sampling/Python/phoenix_hSBM.py", line 4, in <module>
Traceback (most recent call last):
  File "/hpcfs/users/a1670295/Sampling/Python/phoenix_hSBM.py", line 4, in <module>
Traceback (most recent call last):
  File "/hpcfs/users/a1670295/Sampling/Python/phoenix_hSBM.py", line 4, in <module>
./my_program.sh: line 16: /hpcfs/users/a1670295/myconda/envs/gt/bin/python3.9: Argument list too long
    from sbmtm import sbmtm
  File "/hpcfs/users/a1670295/Sampling/Python/sbmtm.py", line 8, in <module>
  File "/hpcfs/users/a1670295/myconda/envs/gt/lib/python3.9/site-packages/graph_tool/draw/cairo_draw.py", line 64, in <module>
  File "/hpcfs/users/a1670295/myconda/envs/gt/lib/python3.9/site-packages/jedi/inference/compiled/__init__.py", line 4, in <module>
Traceback (most recent call last):
Traceback (most recent call last):
Traceback (most recent call last):
  File "/hpcfs/users/a1670295/Sampling/Python/phoenix_hSBM.py", line 4, in <module>
  File "/hpcfs/users/a1670295/Sampling/Python/phoenix_hSBM.py", line 4, in <module>
  File "/hpcfs/users/a1670295/Sampling/Python/phoenix_hSBM.py", line 4, in <module>
    from sbmtm import sbmtm
  File "/hpcfs/users/a1670295/Sampling/Python/sbmtm.py", line 8, in <module>
    from jedi.inference.compiled.value import CompiledValue, CompiledName, \
  File "/hpcfs/users/a1670295/myconda/envs/gt/lib/python3.9/site-packages/jedi/inference/compiled/value.py", line 13, in <module>
    import IPython.display
  File "/hpcfs/users/a1670295/myconda/envs/gt/lib/python3.9/site-packages/IPython/__init__.py", line 56, in <module>
    import graph_tool.all as gt
  File "/hpcfs/users/a1670295/myconda/envs/gt/lib/python3.9/site-packages/graph_tool/all.py", line 34, in <module>
    from sbmtm import sbmtm
  File "/hpcfs/users/a1670295/Sampling/Python/sbmtm.py", line 8, in <module>
    from sbmtm import sbmtm
  File "/hpcfs/users/a1670295/Sampling/Python/sbmtm.py", line 8, in <module>
    from sbmtm import sbmtm
  File "/hpcfs/users/a1670295/Sampling/Python/sbmtm.py", line 8, in <module>
    from .terminal.embed import embed
  File "/hpcfs/users/a1670295/myconda/envs/gt/lib/python3.9/site-packages/IPython/terminal/embed.py", line 15, in <module>
    import graph_tool.all as gt
  File "/hpcfs/users/a1670295/myconda/envs/gt/lib/python3.9/site-packages/graph_tool/all.py", line 34, in <module>
    import graph_tool.all as gt
  File "/hpcfs/users/a1670295/myconda/envs/gt/lib/python3.9/site-packages/graph_tool/all.py", line 34, in <module>
    from graph_tool.draw import *
  File "/hpcfs/users/a1670295/myconda/envs/gt/lib/python3.9/site-packages/graph_tool/draw/__init__.py", line 876, in <module>
    import graph_tool.all as gt
  File "/hpcfs/users/a1670295/myconda/envs/gt/lib/python3.9/site-packages/graph_tool/all.py", line 34, in <module>
    from IPython.core.interactiveshell import DummyMod, InteractiveShell
  File "/hpcfs/users/a1670295/myconda/envs/gt/lib/python3.9/site-packages/IPython/core/interactiveshell.py", line 40, in <module>
    from graph_tool.draw import *
  File "/hpcfs/users/a1670295/myconda/envs/gt/lib/python3.9/site-packages/graph_tool/draw/__init__.py", line 876, in <module>
    from graph_tool.draw import *
  File "/hpcfs/users/a1670295/myconda/envs/gt/lib/python3.9/site-packages/graph_tool/draw/__init__.py", line 876, in <module>
    from . cairo_draw import graph_draw, cairo_draw, \
  File "/hpcfs/users/a1670295/myconda/envs/gt/lib/python3.9/site-packages/graph_tool/draw/cairo_draw.py", line 64, in <module>
    from graph_tool.draw import *
  File "/hpcfs/users/a1670295/myconda/envs/gt/lib/python3.9/site-packages/graph_tool/draw/__init__.py", line 876, in <module>
    from . cairo_draw import graph_draw, cairo_draw, \
  File "/hpcfs/users/a1670295/myconda/envs/gt/lib/python3.9/site-packages/graph_tool/draw/cairo_draw.py", line 64, in <module>
    from . cairo_draw import graph_draw, cairo_draw, \
  File "/hpcfs/users/a1670295/myconda/envs/gt/lib/python3.9/site-packages/graph_tool/draw/cairo_draw.py", line 64, in <module>
    from IPython.core.alias import Alias, AliasManager
  File "<frozen importlib._bootstrap>", line 1007, in _find_and_load
    from . cairo_draw import graph_draw, cairo_draw, \
  File "/hpcfs/users/a1670295/myconda/envs/gt/lib/python3.9/site-packages/graph_tool/draw/cairo_draw.py", line 64, in <module>
    import IPython.display
  File "/hpcfs/users/a1670295/myconda/envs/gt/lib/python3.9/site-packages/IPython/__init__.py", line 56, in <module>
    import IPython.display
  File "/hpcfs/users/a1670295/myconda/envs/gt/lib/python3.9/site-packages/IPython/__init__.py", line 56, in <module>
    import IPython.display
  File "/hpcfs/users/a1670295/myconda/envs/gt/lib/python3.9/site-packages/IPython/__init__.py", line 56, in <module>
    import IPython.display
  File "/hpcfs/users/a1670295/myconda/envs/gt/lib/python3.9/site-packages/IPython/__init__.py", line 56, in <module>
    from .terminal.embed import embed
  File "/hpcfs/users/a1670295/myconda/envs/gt/lib/python3.9/site-packages/IPython/terminal/embed.py", line 16, in <module>
    from .terminal.embed import embed
  File "/hpcfs/users/a1670295/myconda/envs/gt/lib/python3.9/site-packages/IPython/terminal/embed.py", line 16, in <module>
    from .terminal.embed import embed
  File "/hpcfs/users/a1670295/myconda/envs/gt/lib/python3.9/site-packages/IPython/terminal/embed.py", line 16, in <module>
    from .terminal.embed import embed
  File "/hpcfs/users/a1670295/myconda/envs/gt/lib/python3.9/site-packages/IPython/terminal/embed.py", line 16, in <module>
    from IPython.terminal.interactiveshell import TerminalInteractiveShell
  File "/hpcfs/users/a1670295/myconda/envs/gt/lib/python3.9/site-packages/IPython/terminal/interactiveshell.py", line 35, in <module>
    from jedi.inference.filters import AbstractFilter
  File "/hpcfs/users/a1670295/myconda/envs/gt/lib/python3.9/site-packages/jedi/inference/filters.py", line 17, in <module>
  File "<frozen importlib._bootstrap>", line 986, in _find_and_load_unlocked
  File "<frozen importlib._bootstrap>", line 680, in _load_unlocked
  File "<frozen importlib._bootstrap_external>", line 786, in exec_module
    from IPython.terminal.interactiveshell import TerminalInteractiveShell
  File "/hpcfs/users/a1670295/myconda/envs/gt/lib/python3.9/site-packages/IPython/terminal/interactiveshell.py", line 35, in <module>
    from IPython.terminal.interactiveshell import TerminalInteractiveShell
  File "/hpcfs/users/a1670295/myconda/envs/gt/lib/python3.9/site-packages/IPython/terminal/interactiveshell.py", line 35, in <module>
    from IPython.terminal.interactiveshell import TerminalInteractiveShell
  File "/hpcfs/users/a1670295/myconda/envs/gt/lib/python3.9/site-packages/IPython/terminal/interactiveshell.py", line 35, in <module>
    from .debugger import TerminalPdb, Pdb
  File "/hpcfs/users/a1670295/myconda/envs/gt/lib/python3.9/site-packages/IPython/terminal/debugger.py", line 8, in <module>
    from .debugger import TerminalPdb, Pdb
  File "/hpcfs/users/a1670295/myconda/envs/gt/lib/python3.9/site-packages/IPython/terminal/debugger.py", line 8, in <module>
    from .debugger import TerminalPdb, Pdb
  File "/hpcfs/users/a1670295/myconda/envs/gt/lib/python3.9/site-packages/IPython/terminal/debugger.py", line 8, in <module>
    from jedi.inference.names import TreeNameDefinition, ParamName, \
  File "/hpcfs/users/a1670295/myconda/envs/gt/lib/python3.9/site-packages/jedi/inference/names.py", line 11, in <module>
    from IPython.core.completer import IPCompleter
  File "/hpcfs/users/a1670295/myconda/envs/gt/lib/python3.9/site-packages/IPython/core/completer.py", line 146, in <module>
    from .debugger import TerminalPdb, Pdb
  File "/hpcfs/users/a1670295/myconda/envs/gt/lib/python3.9/site-packages/IPython/terminal/debugger.py", line 8, in <module>
    from IPython.core.completer import IPCompleter
  File "/hpcfs/users/a1670295/myconda/envs/gt/lib/python3.9/site-packages/IPython/core/completer.py", line 146, in <module>
  File "<frozen importlib._bootstrap_external>", line 922, in get_code
  File "<frozen importlib._bootstrap_external>", line 980, in get_data
    from IPython.core.completer import IPCompleter
  File "/hpcfs/users/a1670295/myconda/envs/gt/lib/python3.9/site-packages/IPython/core/completer.py", line 146, in <module>
OSError: [Errno 12] Cannot allocate memory
    import jedi
  File "/hpcfs/users/a1670295/myconda/envs/gt/lib/python3.9/site-packages/jedi/__init__.py", line 32, in <module>
    import jedi
  File "/hpcfs/users/a1670295/myconda/envs/gt/lib/python3.9/site-packages/jedi/__init__.py", line 32, in <module>
    from jedi.inference import docstrings
  File "<frozen importlib._bootstrap>", line 1007, in _find_and_load
  File "<frozen importlib._bootstrap>", line 986, in _find_and_load_unlocked
  File "<frozen importlib._bootstrap>", line 680, in _load_unlocked
  File "<frozen importlib._bootstrap_external>", line 786, in exec_module
  File "<frozen importlib._bootstrap_external>", line 922, in get_code
  File "<frozen importlib._bootstrap_external>", line 980, in get_data
OSError: [Errno 12] Cannot allocate memory
    import jedi
  File "/hpcfs/users/a1670295/myconda/envs/gt/lib/python3.9/site-packages/jedi/__init__.py", line 32, in <module>
    from IPython.core.completer import IPCompleter
  File "/hpcfs/users/a1670295/myconda/envs/gt/lib/python3.9/site-packages/IPython/core/completer.py", line 146, in <module>
    from jedi.api import Script, Interpreter, set_debug_function, preload_module
  File "/hpcfs/users/a1670295/myconda/envs/gt/lib/python3.9/site-packages/jedi/api/__init__.py", line 22, in <module>
    import jedi
  File "/hpcfs/users/a1670295/myconda/envs/gt/lib/python3.9/site-packages/jedi/__init__.py", line 32, in <module>
    from jedi.api import Script, Interpreter, set_debug_function, preload_module
  File "/hpcfs/users/a1670295/myconda/envs/gt/lib/python3.9/site-packages/jedi/api/__init__.py", line 22, in <module>
    from jedi.api import Script, Interpreter, set_debug_function, preload_module
  File "/hpcfs/users/a1670295/myconda/envs/gt/lib/python3.9/site-packages/jedi/api/__init__.py", line 22, in <module>
    from jedi.api import classes
  File "/hpcfs/users/a1670295/myconda/envs/gt/lib/python3.9/site-packages/jedi/api/classes.py", line 31, in <module>
    from jedi.api.keywords import KeywordName
  File "/hpcfs/users/a1670295/myconda/envs/gt/lib/python3.9/site-packages/jedi/api/keywords.py", line 9, in <module>
    from jedi.api import Script, Interpreter, set_debug_function, preload_module
  File "/hpcfs/users/a1670295/myconda/envs/gt/lib/python3.9/site-packages/jedi/api/__init__.py", line 22, in <module>
    from jedi.api import classes
  File "/hpcfs/users/a1670295/myconda/envs/gt/lib/python3.9/site-packages/jedi/api/classes.py", line 31, in <module>
    from jedi.api import classes
  File "/hpcfs/users/a1670295/myconda/envs/gt/lib/python3.9/site-packages/jedi/api/classes.py", line 24, in <module>
    from jedi.api.keywords import KeywordName
  File "/hpcfs/users/a1670295/myconda/envs/gt/lib/python3.9/site-packages/jedi/api/keywords.py", line 9, in <module>
    from jedi.inference.utils import unite
  File "/hpcfs/users/a1670295/myconda/envs/gt/lib/python3.9/site-packages/jedi/inference/__init__.py", line 70, in <module>
    from jedi.inference import imports
  File "/hpcfs/users/a1670295/myconda/envs/gt/lib/python3.9/site-packages/jedi/inference/imports.py", line 29, in <module>
    from pydoc_data import topics  # type: ignore[import]
  File "<frozen importlib._bootstrap>", line 1007, in _find_and_load
    from jedi.inference.gradual.typeshed import import_module_decorator, \
  File "<frozen importlib._bootstrap>", line 1007, in _find_and_load
  File "<frozen importlib._bootstrap>", line 986, in _find_and_load_unlocked
  File "<frozen importlib._bootstrap>", line 680, in _load_unlocked
  File "<frozen importlib._bootstrap_external>", line 786, in exec_module
  File "<frozen importlib._bootstrap_external>", line 922, in get_code
  File "<frozen importlib._bootstrap_external>", line 980, in get_data
  File "<frozen importlib._bootstrap>", line 982, in _find_and_load_unlocked
  File "<frozen importlib._bootstrap>", line 925, in _find_spec
  File "<frozen importlib._bootstrap_external>", line 1349, in find_spec
  File "<frozen importlib._bootstrap_external>", line 1321, in _get_spec
  File "<frozen importlib._bootstrap_external>", line 1450, in find_spec
  File "<frozen importlib._bootstrap_external>", line 1490, in _fill_cache
OSError: [Errno 12] Cannot allocate memory
OSError: [Errno 12] Cannot allocate memory: '/hpcfs/users/a1670295/myconda/envs/gt/lib/python3.9/site-packages/jedi/inference/gradual'
./my_program.sh: line 16: /hpcfs/users/a1670295/myconda/envs/gt/bin/python3.9: Argument list too long
./my_program.sh: line 16: /hpcfs/users/a1670295/myconda/envs/gt/bin/python3.9: Argument list too long
./my_program.sh: line 16: /hpcfs/users/a1670295/myconda/envs/gt/bin/python3.9: Argument list too long
./my_program.sh: line 16: /hpcfs/users/a1670295/myconda/envs/gt/bin/python3.9: Argument list too long
./my_program.sh: line 16: /hpcfs/users/a1670295/myconda/envs/gt/bin/python3.9: Argument list too long
./my_program.sh: line 16: /hpcfs/users/a1670295/myconda/envs/gt/bin/python3.9: Argument list too long
./my_program.sh: line 16: /hpcfs/users/a1670295/myconda/envs/gt/bin/python3.9: Bad address
./my_program.sh: line 16: /hpcfs/users/a1670295/myconda/envs/gt/bin/python3.9: Argument list too long
./my_program.sh: line 16: /hpcfs/users/a1670295/myconda/envs/gt/bin/python3.9: Argument list too long
./my_program.sh: line 16: /hpcfs/users/a1670295/myconda/envs/gt/bin/python3.9: Argument list too long
--------------------------------------------------------------------------
Primary job  terminated normally, but 1 process returned
a non-zero exit code. Per user-direction, the job has been aborted.
--------------------------------------------------------------------------
Traceback (most recent call last):
  File "/hpcfs/users/a1670295/Sampling/Python/phoenix_tree_dist.py", line 1, in <module>
    import pandas as pd
  File "/hpcfs/users/a1670295/myconda/envs/gt/lib/python3.9/site-packages/pandas/__init__.py", line 11, in <module>
    __import__(dependency)
  File "/hpcfs/users/a1670295/myconda/envs/gt/lib/python3.9/site-packages/numpy/__init__.py", line 145, in <module>
    from . import core
  File "/hpcfs/users/a1670295/myconda/envs/gt/lib/python3.9/site-packages/numpy/core/__init__.py", line 22, in <module>
    from . import multiarray
  File "/hpcfs/users/a1670295/myconda/envs/gt/lib/python3.9/site-packages/numpy/core/multiarray.py", line 12, in <module>
    from . import overrides
  File "/hpcfs/users/a1670295/myconda/envs/gt/lib/python3.9/site-packages/numpy/core/overrides.py", line 9, in <module>
    from numpy.compat._inspect import getargspec
  File "/hpcfs/users/a1670295/myconda/envs/gt/lib/python3.9/site-packages/numpy/compat/__init__.py", line 12, in <module>
    from . import py3k
  File "/hpcfs/users/a1670295/myconda/envs/gt/lib/python3.9/site-packages/numpy/compat/py3k.py", line 21, in <module>
    from pathlib import Path
  File "/hpcfs/users/a1670295/myconda/envs/gt/lib/python3.9/pathlib.py", line 13, in <module>
    from urllib.parse import quote_from_bytes as urlquote_from_bytes
  File "<frozen importlib._bootstrap>", line 1007, in _find_and_load
  File "<frozen importlib._bootstrap>", line 986, in _find_and_load_unlocked
  File "<frozen importlib._bootstrap>", line 680, in _load_unlocked
  File "<frozen importlib._bootstrap_external>", line 786, in exec_module
  File "<frozen importlib._bootstrap_external>", line 922, in get_code
  File "<frozen importlib._bootstrap_external>", line 980, in get_data
OSError: [Errno 12] Cannot allocate memory
Traceback (most recent call last):
  File "/hpcfs/users/a1670295/Sampling/Python/phoenix_hSBM.py", line 4, in <module>
    from sbmtm import sbmtm
  File "/hpcfs/users/a1670295/Sampling/Python/sbmtm.py", line 8, in <module>
    import graph_tool.all as gt
  File "/hpcfs/users/a1670295/myconda/envs/gt/lib/python3.9/site-packages/graph_tool/all.py", line 34, in <module>
    from graph_tool.draw import *
  File "/hpcfs/users/a1670295/myconda/envs/gt/lib/python3.9/site-packages/graph_tool/draw/__init__.py", line 876, in <module>
    from . cairo_draw import graph_draw, cairo_draw, \
  File "/hpcfs/users/a1670295/myconda/envs/gt/lib/python3.9/site-packages/graph_tool/draw/cairo_draw.py", line 64, in <module>
    import IPython.display
  File "/hpcfs/users/a1670295/myconda/envs/gt/lib/python3.9/site-packages/IPython/__init__.py", line 56, in <module>
    from .terminal.embed import embed
  File "/hpcfs/users/a1670295/myconda/envs/gt/lib/python3.9/site-packages/IPython/terminal/embed.py", line 16, in <module>
    from IPython.terminal.interactiveshell import TerminalInteractiveShell
  File "/hpcfs/users/a1670295/myconda/envs/gt/lib/python3.9/site-packages/IPython/terminal/interactiveshell.py", line 35, in <module>
    from .debugger import TerminalPdb, Pdb
  File "/hpcfs/users/a1670295/myconda/envs/gt/lib/python3.9/site-packages/IPython/terminal/debugger.py", line 8, in <module>
Traceback (most recent call last):
  File "/hpcfs/users/a1670295/Sampling/Python/phoenix_tree_dist.py", line 1, in <module>
    import pandas as pd
  File "/hpcfs/users/a1670295/myconda/envs/gt/lib/python3.9/site-packages/pandas/__init__.py", line 11, in <module>
    __import__(dependency)
  File "/hpcfs/users/a1670295/myconda/envs/gt/lib/python3.9/site-packages/numpy/__init__.py", line 145, in <module>
Traceback (most recent call last):
  File "/hpcfs/users/a1670295/Sampling/Python/phoenix_tree_dist.py", line 1, in <module>
Traceback (most recent call last):
  File "/hpcfs/users/a1670295/Sampling/Python/phoenix_tree_dist.py", line 1, in <module>
    from . import core
  File "/hpcfs/users/a1670295/myconda/envs/gt/lib/python3.9/site-packages/numpy/core/__init__.py", line 72, in <module>
Traceback (most recent call last):
  File "/hpcfs/users/a1670295/Sampling/Python/phoenix_tree_dist.py", line 1, in <module>
    from . import numeric
  File "/hpcfs/users/a1670295/myconda/envs/gt/lib/python3.9/site-packages/numpy/core/numeric.py", line 23, in <module>
    from . import shape_base
  File "/hpcfs/users/a1670295/myconda/envs/gt/lib/python3.9/site-packages/numpy/core/shape_base.py", line 13, in <module>
    import pandas as pd
  File "/hpcfs/users/a1670295/myconda/envs/gt/lib/python3.9/site-packages/pandas/__init__.py", line 11, in <module>
    __import__(dependency)
  File "/hpcfs/users/a1670295/myconda/envs/gt/lib/python3.9/site-packages/numpy/__init__.py", line 145, in <module>
    import pandas as pd
  File "/hpcfs/users/a1670295/myconda/envs/gt/lib/python3.9/site-packages/pandas/__init__.py", line 11, in <module>
    from . import core
  File "/hpcfs/users/a1670295/myconda/envs/gt/lib/python3.9/site-packages/numpy/core/__init__.py", line 81, in <module>
    import pandas as pd
  File "/hpcfs/users/a1670295/myconda/envs/gt/lib/python3.9/site-packages/pandas/__init__.py", line 11, in <module>
    __import__(dependency)
  File "/hpcfs/users/a1670295/myconda/envs/gt/lib/python3.9/site-packages/numpy/__init__.py", line 148, in <module>
    from . import lib
  File "/hpcfs/users/a1670295/myconda/envs/gt/lib/python3.9/site-packages/numpy/lib/__init__.py", line 25, in <module>
    from . import fromnumeric as _from_nx
  File "/hpcfs/users/a1670295/myconda/envs/gt/lib/python3.9/site-packages/numpy/core/fromnumeric.py", line 15, in <module>
    from .index_tricks import *
  File "/hpcfs/users/a1670295/myconda/envs/gt/lib/python3.9/site-packages/numpy/lib/index_tricks.py", line 12, in <module>
    import numpy.matrixlib as matrixlib
  File "/hpcfs/users/a1670295/myconda/envs/gt/lib/python3.9/site-packages/numpy/matrixlib/__init__.py", line 4, in <module>
    from . import function_base
  File "<frozen importlib._bootstrap>", line 1007, in _find_and_load
  File "<frozen importlib._bootstrap>", line 986, in _find_and_load_unlocked
  File "<frozen importlib._bootstrap>", line 680, in _load_unlocked
  File "<frozen importlib._bootstrap_external>", line 786, in exec_module
  File "<frozen importlib._bootstrap_external>", line 922, in get_code
  File "<frozen importlib._bootstrap_external>", line 980, in get_data
    from .defmatrix import *
  File "/hpcfs/users/a1670295/myconda/envs/gt/lib/python3.9/site-packages/numpy/matrixlib/defmatrix.py", line 11, in <module>
OSError: [Errno 12] Cannot allocate memory
    __import__(dependency)
  File "/hpcfs/users/a1670295/myconda/envs/gt/lib/python3.9/site-packages/numpy/__init__.py", line 148, in <module>
    from . import lib
  File "/hpcfs/users/a1670295/myconda/envs/gt/lib/python3.9/site-packages/numpy/lib/__init__.py", line 27, in <module>
    from .nanfunctions import *
  File "<frozen importlib._bootstrap>", line 1007, in _find_and_load
  File "<frozen importlib._bootstrap>", line 986, in _find_and_load_unlocked
  File "<frozen importlib._bootstrap>", line 680, in _load_unlocked
  File "<frozen importlib._bootstrap_external>", line 786, in exec_module
  File "<frozen importlib._bootstrap_external>", line 922, in get_code
  File "<frozen importlib._bootstrap_external>", line 980, in get_data
OSError: [Errno 12] Cannot allocate memory
    from . import _methods
  File "<frozen importlib._bootstrap>", line 1007, in _find_and_load
  File "<frozen importlib._bootstrap>", line 986, in _find_and_load_unlocked
  File "<frozen importlib._bootstrap>", line 680, in _load_unlocked
  File "<frozen importlib._bootstrap_external>", line 786, in exec_module
  File "<frozen importlib._bootstrap_external>", line 922, in get_code
  File "<frozen importlib._bootstrap_external>", line 980, in get_data
OSError: [Errno 12] Cannot allocate memory
    from numpy.linalg import matrix_power
  File "/hpcfs/users/a1670295/myconda/envs/gt/lib/python3.9/site-packages/numpy/linalg/__init__.py", line 73, in <module>
    from .linalg import *
  File "<frozen importlib._bootstrap>", line 1007, in _find_and_load
  File "<frozen importlib._bootstrap>", line 982, in _find_and_load_unlocked
  File "<frozen importlib._bootstrap>", line 925, in _find_spec
  File "<frozen importlib._bootstrap_external>", line 1349, in find_spec
  File "<frozen importlib._bootstrap_external>", line 1321, in _get_spec
  File "<frozen importlib._bootstrap_external>", line 1450, in find_spec
  File "<frozen importlib._bootstrap_external>", line 1490, in _fill_cache
OSError: [Errno 12] Cannot allocate memory: '/hpcfs/users/a1670295/myconda/envs/gt/lib/python3.9/site-packages/numpy/linalg'
Traceback (most recent call last):
  File "/hpcfs/users/a1670295/Sampling/Python/phoenix_tree_dist.py", line 1, in <module>
    import pandas as pd
  File "/hpcfs/users/a1670295/myconda/envs/gt/lib/python3.9/site-packages/pandas/__init__.py", line 11, in <module>
    __import__(dependency)
  File "/hpcfs/users/a1670295/myconda/envs/gt/lib/python3.9/site-packages/numpy/__init__.py", line 148, in <module>
    from . import lib
  File "/hpcfs/users/a1670295/myconda/envs/gt/lib/python3.9/site-packages/numpy/lib/__init__.py", line 25, in <module>
    from .index_tricks import *
  File "/hpcfs/users/a1670295/myconda/envs/gt/lib/python3.9/site-packages/numpy/lib/index_tricks.py", line 12, in <module>
    import numpy.matrixlib as matrixlib
  File "/hpcfs/users/a1670295/myconda/envs/gt/lib/python3.9/site-packages/numpy/matrixlib/__init__.py", line 4, in <module>
    from .defmatrix import *
  File "/hpcfs/users/a1670295/myconda/envs/gt/lib/python3.9/site-packages/numpy/matrixlib/defmatrix.py", line 11, in <module>
    from numpy.linalg import matrix_power
  File "/hpcfs/users/a1670295/myconda/envs/gt/lib/python3.9/site-packages/numpy/linalg/__init__.py", line 73, in <module>
    from .linalg import *
  File "<frozen importlib._bootstrap>", line 1007, in _find_and_load
  File "<frozen importlib._bootstrap>", line 982, in _find_and_load_unlocked
  File "<frozen importlib._bootstrap>", line 925, in _find_spec
  File "<frozen importlib._bootstrap_external>", line 1349, in find_spec
  File "<frozen importlib._bootstrap_external>", line 1321, in _get_spec
  File "<frozen importlib._bootstrap_external>", line 1450, in find_spec
  File "<frozen importlib._bootstrap_external>", line 1490, in _fill_cache
OSError: [Errno 12] Cannot allocate memory: '/hpcfs/users/a1670295/myconda/envs/gt/lib/python3.9/site-packages/numpy/linalg'
    from IPython.core.completer import IPCompleter
  File "/hpcfs/users/a1670295/myconda/envs/gt/lib/python3.9/site-packages/IPython/core/completer.py", line 146, in <module>
    import jedi
  File "/hpcfs/users/a1670295/myconda/envs/gt/lib/python3.9/site-packages/jedi/__init__.py", line 32, in <module>
    from jedi.api import Script, Interpreter, set_debug_function, preload_module
  File "/hpcfs/users/a1670295/myconda/envs/gt/lib/python3.9/site-packages/jedi/api/__init__.py", line 22, in <module>
    from jedi.api import classes
  File "/hpcfs/users/a1670295/myconda/envs/gt/lib/python3.9/site-packages/jedi/api/classes.py", line 31, in <module>
    from jedi.api.keywords import KeywordName
  File "/hpcfs/users/a1670295/myconda/envs/gt/lib/python3.9/site-packages/jedi/api/keywords.py", line 9, in <module>
    from pydoc_data import topics  # type: ignore[import]
  File "<frozen importlib._bootstrap>", line 1007, in _find_and_load
  File "<frozen importlib._bootstrap>", line 986, in _find_and_load_unlocked
  File "<frozen importlib._bootstrap>", line 680, in _load_unlocked
  File "<frozen importlib._bootstrap_external>", line 786, in exec_module
  File "<frozen importlib._bootstrap_external>", line 918, in get_code
  File "<frozen importlib._bootstrap_external>", line 587, in _compile_bytecode
EOFError: marshal data too short
Traceback (most recent call last):
  File "/hpcfs/users/a1670295/Sampling/Python/phoenix_tree_dist.py", line 1, in <module>
    import pandas as pd
  File "/hpcfs/users/a1670295/myconda/envs/gt/lib/python3.9/site-packages/pandas/__init__.py", line 16, in <module>
    raise ImportError(
ImportError: Unable to import required dependencies:
numpy: /hpcfs/users/a1670295/myconda/envs/gt/lib/python3.9/site-packages/numpy/random/_mt19937.cpython-39-x86_64-linux-gnu.so: cannot read file data: Cannot allocate memory
Traceback (most recent call last):
  File "/hpcfs/users/a1670295/Sampling/Python/phoenix_tree_dist.py", line 1, in <module>
    import pandas as pd
  File "/hpcfs/users/a1670295/myconda/envs/gt/lib/python3.9/site-packages/pandas/__init__.py", line 11, in <module>
    __import__(dependency)
  File "/hpcfs/users/a1670295/myconda/envs/gt/lib/python3.9/site-packages/numpy/__init__.py", line 148, in <module>
    from . import lib
  File "/hpcfs/users/a1670295/myconda/envs/gt/lib/python3.9/site-packages/numpy/lib/__init__.py", line 25, in <module>
    from .index_tricks import *
  File "/hpcfs/users/a1670295/myconda/envs/gt/lib/python3.9/site-packages/numpy/lib/index_tricks.py", line 12, in <module>
    import numpy.matrixlib as matrixlib
  File "/hpcfs/users/a1670295/myconda/envs/gt/lib/python3.9/site-packages/numpy/matrixlib/__init__.py", line 4, in <module>
    from .defmatrix import *
  File "/hpcfs/users/a1670295/myconda/envs/gt/lib/python3.9/site-packages/numpy/matrixlib/defmatrix.py", line 11, in <module>
    from numpy.linalg import matrix_power
  File "/hpcfs/users/a1670295/myconda/envs/gt/lib/python3.9/site-packages/numpy/linalg/__init__.py", line 73, in <module>
    from .linalg import *
  File "<frozen importlib._bootstrap>", line 1007, in _find_and_load
  File "<frozen importlib._bootstrap>", line 982, in _find_and_load_unlocked
  File "<frozen importlib._bootstrap>", line 925, in _find_spec
  File "<frozen importlib._bootstrap_external>", line 1349, in find_spec
  File "<frozen importlib._bootstrap_external>", line 1321, in _get_spec
  File "<frozen importlib._bootstrap_external>", line 1450, in find_spec
  File "<frozen importlib._bootstrap_external>", line 1490, in _fill_cache
OSError: [Errno 12] Cannot allocate memory: '/hpcfs/users/a1670295/myconda/envs/gt/lib/python3.9/site-packages/numpy/linalg'
Traceback (most recent call last):
  File "/hpcfs/users/a1670295/Sampling/Python/phoenix_tree_dist.py", line 1, in <module>
    import pandas as pd
  File "/hpcfs/users/a1670295/myconda/envs/gt/lib/python3.9/site-packages/pandas/__init__.py", line 11, in <module>
    __import__(dependency)
  File "/hpcfs/users/a1670295/myconda/envs/gt/lib/python3.9/site-packages/numpy/__init__.py", line 148, in <module>
    from . import lib
  File "/hpcfs/users/a1670295/myconda/envs/gt/lib/python3.9/site-packages/numpy/lib/__init__.py", line 21, in <module>
    from . import scimath as emath
  File "/hpcfs/users/a1670295/myconda/envs/gt/lib/python3.9/site-packages/numpy/lib/scimath.py", line 38, in <module>
    from numpy.lib.type_check import isreal
  File "/hpcfs/users/a1670295/myconda/envs/gt/lib/python3.9/site-packages/numpy/lib/type_check.py", line 16, in <module>
    from .ufunclike import isneginf, isposinf
  File "<frozen importlib._bootstrap>", line 1007, in _find_and_load
  File "<frozen importlib._bootstrap>", line 986, in _find_and_load_unlocked
  File "<frozen importlib._bootstrap>", line 680, in _load_unlocked
  File "<frozen importlib._bootstrap_external>", line 786, in exec_module
  File "<frozen importlib._bootstrap_external>", line 922, in get_code
  File "<frozen importlib._bootstrap_external>", line 980, in get_data
OSError: [Errno 12] Cannot allocate memory
Traceback (most recent call last):
  File "/hpcfs/users/a1670295/Sampling/Python/phoenix_hSBM.py", line 4, in <module>
    from sbmtm import sbmtm
  File "/hpcfs/users/a1670295/Sampling/Python/sbmtm.py", line 8, in <module>
    import graph_tool.all as gt
  File "/hpcfs/users/a1670295/myconda/envs/gt/lib/python3.9/site-packages/graph_tool/all.py", line 34, in <module>
    from graph_tool.draw import *
  File "/hpcfs/users/a1670295/myconda/envs/gt/lib/python3.9/site-packages/graph_tool/draw/__init__.py", line 876, in <module>
    from . cairo_draw import graph_draw, cairo_draw, \
  File "/hpcfs/users/a1670295/myconda/envs/gt/lib/python3.9/site-packages/graph_tool/draw/cairo_draw.py", line 64, in <module>
    import IPython.display
  File "/hpcfs/users/a1670295/myconda/envs/gt/lib/python3.9/site-packages/IPython/__init__.py", line 56, in <module>
    from .terminal.embed import embed
  File "/hpcfs/users/a1670295/myconda/envs/gt/lib/python3.9/site-packages/IPython/terminal/embed.py", line 16, in <module>
    from IPython.terminal.interactiveshell import TerminalInteractiveShell
  File "/hpcfs/users/a1670295/myconda/envs/gt/lib/python3.9/site-packages/IPython/terminal/interactiveshell.py", line 35, in <module>
    from .debugger import TerminalPdb, Pdb
  File "/hpcfs/users/a1670295/myconda/envs/gt/lib/python3.9/site-packages/IPython/terminal/debugger.py", line 8, in <module>
    from IPython.core.completer import IPCompleter
  File "/hpcfs/users/a1670295/myconda/envs/gt/lib/python3.9/site-packages/IPython/core/completer.py", line 146, in <module>
    import jedi
  File "/hpcfs/users/a1670295/myconda/envs/gt/lib/python3.9/site-packages/jedi/__init__.py", line 32, in <module>
    from jedi.api import Script, Interpreter, set_debug_function, preload_module
  File "/hpcfs/users/a1670295/myconda/envs/gt/lib/python3.9/site-packages/jedi/api/__init__.py", line 22, in <module>
    from jedi.api import classes
  File "/hpcfs/users/a1670295/myconda/envs/gt/lib/python3.9/site-packages/jedi/api/classes.py", line 31, in <module>
    from jedi.api.keywords import KeywordName
  File "/hpcfs/users/a1670295/myconda/envs/gt/lib/python3.9/site-packages/jedi/api/keywords.py", line 9, in <module>
    from pydoc_data import topics  # type: ignore[import]
  File "<frozen importlib._bootstrap>", line 1007, in _find_and_load
  File "<frozen importlib._bootstrap>", line 986, in _find_and_load_unlocked
  File "<frozen importlib._bootstrap>", line 680, in _load_unlocked
  File "<frozen importlib._bootstrap_external>", line 786, in exec_module
  File "<frozen importlib._bootstrap_external>", line 918, in get_code
  File "<frozen importlib._bootstrap_external>", line 587, in _compile_bytecode
EOFError: marshal data too short
Traceback (most recent call last):
  File "/hpcfs/users/a1670295/Sampling/Python/phoenix_tree_dist.py", line 1, in <module>
    import pandas as pd
  File "/hpcfs/users/a1670295/myconda/envs/gt/lib/python3.9/site-packages/pandas/__init__.py", line 11, in <module>
    __import__(dependency)
  File "/hpcfs/users/a1670295/myconda/envs/gt/lib/python3.9/site-packages/numpy/__init__.py", line 145, in <module>
    from . import core
  File "/hpcfs/users/a1670295/myconda/envs/gt/lib/python3.9/site-packages/numpy/core/__init__.py", line 72, in <module>
    from . import numeric
  File "/hpcfs/users/a1670295/myconda/envs/gt/lib/python3.9/site-packages/numpy/core/numeric.py", line 2533, in <module>
    from . import arrayprint
  File "<frozen importlib._bootstrap>", line 1007, in _find_and_load
  File "<frozen importlib._bootstrap>", line 986, in _find_and_load_unlocked
  File "<frozen importlib._bootstrap>", line 680, in _load_unlocked
  File "<frozen importlib._bootstrap_external>", line 786, in exec_module
  File "<frozen importlib._bootstrap_external>", line 922, in get_code
  File "<frozen importlib._bootstrap_external>", line 980, in get_data
OSError: [Errno 12] Cannot allocate memory
Traceback (most recent call last):
  File "/hpcfs/users/a1670295/Sampling/Python/phoenix_tree_dist.py", line 1, in <module>
    import pandas as pd
  File "/hpcfs/users/a1670295/myconda/envs/gt/lib/python3.9/site-packages/pandas/__init__.py", line 11, in <module>
    __import__(dependency)
  File "/hpcfs/users/a1670295/myconda/envs/gt/lib/python3.9/site-packages/numpy/__init__.py", line 155, in <module>
    from . import polynomial
  File "/hpcfs/users/a1670295/myconda/envs/gt/lib/python3.9/site-packages/numpy/polynomial/__init__.py", line 119, in <module>
    from .legendre import Legendre
  File "<frozen importlib._bootstrap>", line 1007, in _find_and_load
  File "<frozen importlib._bootstrap>", line 986, in _find_and_load_unlocked
  File "<frozen importlib._bootstrap>", line 680, in _load_unlocked
  File "<frozen importlib._bootstrap_external>", line 786, in exec_module
  File "<frozen importlib._bootstrap_external>", line 922, in get_code
  File "<frozen importlib._bootstrap_external>", line 980, in get_data
OSError: [Errno 12] Cannot allocate memory
Traceback (most recent call last):
  File "/hpcfs/users/a1670295/Sampling/Python/phoenix_tree_dist.py", line 1, in <module>
    import pandas as pd
  File "/hpcfs/users/a1670295/myconda/envs/gt/lib/python3.9/site-packages/pandas/__init__.py", line 16, in <module>
    raise ImportError(
ImportError: Unable to import required dependencies:
numpy: /hpcfs/users/a1670295/myconda/envs/gt/lib/python3.9/site-packages/numpy/random/mtrand.cpython-39-x86_64-linux-gnu.so: cannot read file data: Cannot allocate memory
    from sbmtm import sbmtm
  File "/hpcfs/users/a1670295/Sampling/Python/sbmtm.py", line 8, in <module>
    import graph_tool.all as gt
  File "/hpcfs/users/a1670295/myconda/envs/gt/lib/python3.9/site-packages/graph_tool/all.py", line 34, in <module>
    from pydoc_data import topics  # type: ignore[import]
  File "<frozen importlib._bootstrap>", line 1007, in _find_and_load
  File "<frozen importlib._bootstrap>", line 986, in _find_and_load_unlocked
  File "<frozen importlib._bootstrap>", line 680, in _load_unlocked
  File "<frozen importlib._bootstrap_external>", line 786, in exec_module
  File "<frozen importlib._bootstrap_external>", line 922, in get_code
  File "<frozen importlib._bootstrap_external>", line 980, in get_data
Traceback (most recent call last):
  File "/hpcfs/users/a1670295/Sampling/Python/phoenix_hSBM.py", line 4, in <module>
Traceback (most recent call last):
  File "/hpcfs/users/a1670295/Sampling/Python/phoenix_hSBM.py", line 4, in <module>
OSError: [Errno 12] Cannot allocate memory
    from jedi.api import classes
  File "/hpcfs/users/a1670295/myconda/envs/gt/lib/python3.9/site-packages/jedi/api/classes.py", line 31, in <module>
    from sbmtm import sbmtm
  File "/hpcfs/users/a1670295/Sampling/Python/sbmtm.py", line 8, in <module>
    import graph_tool.all as gt
  File "/hpcfs/users/a1670295/myconda/envs/gt/lib/python3.9/site-packages/graph_tool/all.py", line 34, in <module>
    from graph_tool.draw import *
  File "/hpcfs/users/a1670295/myconda/envs/gt/lib/python3.9/site-packages/graph_tool/draw/__init__.py", line 876, in <module>
    from . cairo_draw import graph_draw, cairo_draw, \
  File "/hpcfs/users/a1670295/myconda/envs/gt/lib/python3.9/site-packages/graph_tool/draw/cairo_draw.py", line 64, in <module>
    from jedi.api.keywords import KeywordName
  File "/hpcfs/users/a1670295/myconda/envs/gt/lib/python3.9/site-packages/jedi/api/keywords.py", line 9, in <module>
    from pydoc_data import topics  # type: ignore[import]
  File "<frozen importlib._bootstrap>", line 1007, in _find_and_load
  File "<frozen importlib._bootstrap>", line 986, in _find_and_load_unlocked
  File "<frozen importlib._bootstrap>", line 680, in _load_unlocked
  File "<frozen importlib._bootstrap_external>", line 786, in exec_module
  File "<frozen importlib._bootstrap_external>", line 922, in get_code
  File "<frozen importlib._bootstrap_external>", line 980, in get_data
OSError: [Errno 12] Cannot allocate memory
    from sbmtm import sbmtm
  File "/hpcfs/users/a1670295/Sampling/Python/sbmtm.py", line 8, in <module>
    import graph_tool.all as gt
  File "/hpcfs/users/a1670295/myconda/envs/gt/lib/python3.9/site-packages/graph_tool/all.py", line 34, in <module>
    import IPython.display
  File "/hpcfs/users/a1670295/myconda/envs/gt/lib/python3.9/site-packages/IPython/__init__.py", line 56, in <module>
    from graph_tool.draw import *
  File "/hpcfs/users/a1670295/myconda/envs/gt/lib/python3.9/site-packages/graph_tool/draw/__init__.py", line 876, in <module>
    from .terminal.embed import embed
  File "/hpcfs/users/a1670295/myconda/envs/gt/lib/python3.9/site-packages/IPython/terminal/embed.py", line 16, in <module>
    from graph_tool.draw import *
  File "/hpcfs/users/a1670295/myconda/envs/gt/lib/python3.9/site-packages/graph_tool/draw/__init__.py", line 876, in <module>
Python path configuration:
  PYTHONHOME = (not set)
  PYTHONPATH = '/apps/skl/software/GDAL/2.2.3/lib/python3.6/site-packages:/apps/skl/software/GEOS/3.6.2/lib/python3.6/site-packages'
  program name = 'python3.9'
  isolated = 0
  environment = 1
  user site = 1
  import site = 1
  sys._base_executable = '/hpcfs/users/a1670295/myconda/envs/gt/bin/python3.9'
  sys.base_prefix = '/hpcfs/users/a1670295/myconda/envs/gt'
  sys.base_exec_prefix = '/hpcfs/users/a1670295/myconda/envs/gt'
  sys.platlibdir = 'lib'
  sys.executable = '/hpcfs/users/a1670295/myconda/envs/gt/bin/python3.9'
  sys.prefix = '/hpcfs/users/a1670295/myconda/envs/gt'
  sys.exec_prefix = '/hpcfs/users/a1670295/myconda/envs/gt'
  sys.path = [
    '/apps/skl/software/GDAL/2.2.3/lib/python3.6/site-packages',
    '/apps/skl/software/GEOS/3.6.2/lib/python3.6/site-packages',
    '/hpcfs/users/a1670295/myconda/envs/gt/lib/python39.zip',
    '/hpcfs/users/a1670295/myconda/envs/gt/lib/python3.9',
    '/hpcfs/users/a1670295/myconda/envs/gt/lib/python3.9/lib-dynload',
  ]
--------------------------------------------------------------------------
mpirun noticed that process rank 1 with PID 298876 on node r24-gpu6 exited on signal 11 (Segmentation fault).
--------------------------------------------------------------------------
slurmstepd: error: Detected 25732 oom-kill event(s) in step 6535746.batch cgroup. Some of your processes may have been killed by the cgroup out-of-memory handler.
#
#===========================================================================
#HPC1 Job Utilisation Reporting
===========================================================================
Job Name            : script.sh
Job ID              : 6535746
User                : a1670295
Account             : mathsci
Cluster             : hpc1
Partition           : v100cpu
Nodes (List)        : 1,2 (r24-gpu[5-6])
Cores               : 4
GPUs                : 0
State               : OUT_OF_MEMORY
Submit              : 2021-06-10T23:10:27
Start               : 2021-06-10T23:11:31
End                 : 2021-06-10T23:29:38
Walltime reserved   : 01:00:00
Walltime elapsed (%): 00:18:07  (30.2% * reserved)
CPU-time elapsed    : 1.21 core-hours
% CPU used (Total)  :  1.47%    (0.02 core-hours)
% User CPU (Compute):  0.63%    (0.01 core-hours)
% System CPU (I/O)  :  0.84%    (0.01 core-hours)
Mem reserved        : 16G/node
% Mem used (Max)    : 173.44%    (27.75G/node) 
Max Disk Write      : 3.32M     (r24-gpu5,r24-gpu6)
Max Disk Read       : 5.08G     (r24-gpu5,r24-gpu6)
===========================================================================
